Workbook

Sheet Count
A1: Path | B1: Tab | C1: Count | D1: Duration | E1: URL
A2: collect/miscellaneous/Dhaka FM | B2: Lina | C2: =COUNTA(Lina!A2:A1000) -> 64 | D2: =SUM(Lina!B2:B1000) -> 1605.131 | E2: https://docs.google.com/spreadsheets/d/1MWa6Tvw4zXRkw-sT1Z4FkDvYEbXl6LisfYmRs4QaUgo/edit?gid=1682353242#gid=1682353242
A3: collect/read/YouTube/Bangladesh Television (BTV) | B3: MRK | C3: =COUNTA(MRK!A2:A1000) -> 50 | D3: =SUM(MRK!B2:B1000) -> 1500 | E3: https://docs.google.com/spreadsheets/d/1zG1DWj8Uo2fz0FrO7K3VPRZJmjbogsoOJ6_8dRxiwFM/edit?gid=1682353242#gid=1682353242
A4: collect/read/YouTube/Sangsad TV | B4: Dipto | C4: =COUNTA(Dipto!A2:A1000) -> 22 | D4: =SUM(Dipto!B2:B1000) -> 652.908 | E4: https://docs.google.com/spreadsheets/d/1SAKeZ4GYS3XtJ3VK37ysMZSatkqfS7NH3Cp-nBziPqw/edit?gid=1682353242#gid=1682353242
A5: collect/spontaneous/Dhaka FM | B5: Mehadi | C5: =COUNTA(Mehadi!A2:A1000) -> 41 | D5: =SUM(Mehadi!B2:B1000) -> 1053.621 | E5: https://docs.google.com/spreadsheets/d/1V6JmdOW71JtSp5DOttFFQLzJt2Wil6ZQ8f10dGOIJ7k/edit?gid=0#gid=0
A6: collect/spontaneous/Dhaka FM/(বি কুল) BC - PROGRAM | B6: Mashruf-2 | C6: =COUNTA('Mashruf-2'!A8:A1000) -> 47 | D6: =SUM('Mashruf-2'!B8:B1000) -> 1410
A7: collect/spontaneous/Dhaka FM/(হেল্প লাইন) HL - PROGRAM | B7: Nusrat | C7: =COUNTA(Nusrat!A2:A1000) -> 24 | D7: =SUM(Nusrat!B2:B1000) -> 624.631 | E7: https://docs.google.com/spreadsheets/d/1LWrkYRWqqjhjgxdMwjQ1Qm_gmcuQKclfv_z_HOhGK4I/edit?gid=1682353242#gid=1682353242
A8: collect/spontaneous/Facebook/BangladeshBetarNews | B8: Annoor | C8: =COUNTA(Annoor!A2:A1000) -> 71 | D8: =SUM(Annoor!B2:B1000) -> 1069.016 | E8: https://docs.google.com/spreadsheets/d/1sNsvTEjhFAxLcwsjZ1J7CaU0DXftbwyAHeDmpZqDOAI/edit?gid=1682353242#gid=1682353242
A9: collect/spontaneous/YouTube/a2i Bangladesh | B9: STA | C9: =COUNTA(STA!A2:A1000) -> 0 | D9: =SUM(STA!B2:B1000) -> 0 | E9: https://docs.google.com/spreadsheets/d/1UBnDQLBQan7R0Zm5qO8tuyav0U8mcd9uVBMEOwQuf6E/edit?gid=1682353242#gid=1682353242
A10: collect/spontaneous/YouTube/Bangladesh Open University (BOU) | B10: Annoor-2 | C10: =COUNTA('Annoor-2'!A2:A1000) -> 50 | D10: =SUM('Annoor-2'!B2:B1000) -> 1500 | E10: https://docs.google.com/spreadsheets/d/1sNsvTEjhFAxLcwsjZ1J7CaU0DXftbwyAHeDmpZqDOAI/edit?gid=1682353242#gid=1682353242
A11: collect/spontaneous/YouTube/Chapainawabganj TV | B11: Lina-2 | C11: =COUNTA('Lina-2'!A2:A1000) -> 40 | D11: =SUM('Lina-2'!B2:B1000) -> 1200 | E11: https://docs.google.com/spreadsheets/d/1MWa6Tvw4zXRkw-sT1Z4FkDvYEbXl6LisfYmRs4QaUgo/edit?gid=1682353242#gid=1682353242
A12: collect\read\YouTube\TORONGO | B12: Mashruf | C12: =COUNTA(Mashruf!A2:A1000) -> 160 | D12: =SUM(Mashruf!B2:B1000) -> 4800 | E12: https://docs.google.com/spreadsheets/d/1PtILyyZqZN6xk8xuQzHIvifzPUCl9KOtv8lTbbnVLPo/edit?gid=1682353242#gid=1682353242
D17: =SUM(D2:D6)/3600 -> 1.7282389 | E17: Hours

Sheet Sheet14

Sheet Credentials
A1: Instructions | B1: https://docs.google.com/document/d/1Bt2t5DqETxGsRZ6ucLhyW4Lxm9W8TV8tEAb9PES1SRg/edit?tab=t.0
A2: Here’s a video of how to use the tool : | B2: https://drive.google.com/file/d/1GZysFwDonYXQyT1YGkkJ8TwTSeMLhTNp/view?usp=sharing
A5: mehadi | B5: Kx9#mP2vL8qR | C5: collect/spontaneous/Dhaka FM | E5: https://docs.google.com/spreadsheets/d/1V6JmdOW71JtSp5DOttFFQLzJt2Wil6ZQ8f10dGOIJ7k/edit?gid=0#gid=0
A6: annoor | B6: Zt4$nW7jF3xY | C6: collect/spontaneous/Facebook/BangladeshBetarNews | E6: https://docs.google.com/spreadsheets/d/1sNsvTEjhFAxLcwsjZ1J7CaU0DXftbwyAHeDmpZqDOAI/edit?gid=0#gid=0
A7: lina | B7: Bv6&hQ9sM1kE | C7: collect/miscellaneous/Dhaka FM | E7: https://docs.google.com/spreadsheets/d/1MWa6Tvw4zXRkw-sT1Z4FkDvYEbXl6LisfYmRs4QaUgo/edit?gid=0#gid=0
A8: rar | B8: Gp3*rT8cN5wA
A9: dipto | B9: Jm7@uV2bX4zD | C9: collect/read/YouTube/Sangsad TV | E9: https://docs.google.com/spreadsheets/d/1SAKeZ4GYS3XtJ3VK37ysMZSatkqfS7NH3Cp-nBziPqw/edit?gid=0#gid=0
A10: sta | B10: Qw5!yH8fK9pL | C10: collect/spontaneous/YouTube | E10: https://docs.google.com/spreadsheets/d/1UBnDQLBQan7R0Zm5qO8tuyav0U8mcd9uVBMEOwQuf6E/edit?gid=0#gid=0
A11: mrk | B11: Cx2%eR6gJ7nM | C11: collect/read/YouTube/Bangladesh Television (BTV) | E11: https://docs.google.com/spreadsheets/d/1zG1DWj8Uo2fz0FrO7K3VPRZJmjbogsoOJ6_8dRxiwFM/edit?gid=0#gid=0
A12: fa | B12: Fs4^iO1tY3vB
A13: demo | B13: Nz8&aU5hW2qS | C13: collect\read\YouTube\TORONGO | E13: https://docs.google.com/spreadsheets/d/1PtILyyZqZN6xk8xuQzHIvifzPUCl9KOtv8lTbbnVLPo/edit?gid=0#gid=0
B16: npm start
B17: cloudflared tunnel run stt
A20: Read | B20: Bangladesh Television
B21: Torongo
B22: Sangsad TV
A23: Spontaneous | B23: Dhaka FM
B24: Facebook
B25: Youtube
A27: Miscellaneous | B27: Dhaka FM

Sheet Data
A1: Filename | B1: Duration (seconds) | C1: Text | D1: Correct | E1: Word Missing | F1: Spelling Mistake | G1: Word Accuracy | H1: Grammar & Syntax | I1: Proper Noun Recognition | J1: Punctuation & Formatting | K1: Audio Quality | L1: Language Content (if contains more than 10% foreign language) | M1: Notes

Sheet MRK
A1: =IFERROR(__xludf.DUMMYFUNCTION("IMPORTRANGE(""https://docs.google.com/spreadsheets/d/1zG1DWj8Uo2fz0FrO7K3VPRZJmjbogsoOJ6_8dRxiwFM"", ""Data!A:L"")"),"Filename") -> Filename | B1: =IFERROR(__xludf.DUMMYFUNCTION("""COMPUTED_VALUE"""),"Duration (seconds)") -> Duration (seconds) | C1: =IFERROR(__xludf.DUMMYFUNCTION("""COMPUTED_VALUE"""),"Text") -> Text | D1: =IFERROR(__xludf.DUMMYFUNCTION("""COMPUTED_VALUE"""),"Correct") -> Correct | E1: =IFERROR(__xludf.DUMMYFUNCTION("""COMPUTED_VALUE"""),"Word Missing") -> Word Missing | F1: =IFERROR(__xludf.DUMMYFUNCTION("""COMPUTED_VALUE"""),"Spelling Mistake") -> Spelling Mistake | G1: =IFERROR(__xludf.DUMMYFUNCTION("""COMPUTED_VALUE"""),"Word Accuracy") -> Word Accuracy | H1: =IFERROR(__xludf.DUMMYFUNCTION("""COMPUTED_VALUE"""),"Grammar & Syntax") -> Grammar & Syntax | I1: =IFERROR(__xludf.DUMMYFUNCTION("""COMPUTED_VALUE"""),"Proper Noun Recognition") -> Proper Noun Recognition | J1: =IFERROR(__xludf.DUMMYFUNCTION("""COMPUTED_VALUE"""),"Punctuation & Formatting") -> Punctuation & Formatting | K1: =IFERROR(__xludf.DUMMYFUNCTION("""COMPUTED_VALUE"""),"Audio Quality") -> Audio Quality | L1: =IFERROR(__xludf.DUMMYFUNCTION("""COMPUTED_VALUE"""),"Language Content (if contains more than 10% foreign language)") -> Language Content (if contains more than 10% foreign language)
A2: =IFERROR(__xludf.DUMMYFUNCTION("""COMPUTED_VALUE"""),"collect\read\YouTube\Bangladesh Television (BTV)\__yFg8a8Zb4\0289a285-0be7-4e45-b2f2-4e3700ea5348.flac") -> collect\read\YouTube\Bangladesh Television (BTV)\__yFg8a8Zb4\0289a285-0be7-4e45-b2f2-4e3700ea5348.flac | B2: =IFERROR(__xludf.DUMMYFUNCTION("""COMPUTED_VALUE"""),30.0) -> 30 | C2: =IFERROR(__xludf.DUMMYFUNCTION("""COMPUTED_VALUE"""),"প্রায় আশি পঁচাশি পার্সেন্ট মানুষ ঢাকার বাইরে গ্রামে বাস করে এবং এই গ্রামের মানুষগুলো কিন্তু এতদিন পর্যন্ত তাদের বিশ্বাস ছিল বা এখনো পর্যন্ত টুছাম হছেন বিশ্বাস আছে যে করোনা হচ্ছে এটা শহরের অসু করানা হচ্ছে এটা বড় লোকের অসু তো আয় এখনো পর্যন্ত যদি একটা দেশের "&"মানে এত বিশাল জনগোষ্ঠী করোনাকে ওভাবে শিকারী না করে তাহলে এই জনগোষ্ঠীকে আপনি কীভাবে আপনি সোশ্যাল ডিসটেন্সিংয়ের কথা বলেন আপনি মাস্ক পরার কথা বলেন এটা আপনি তো রাতারাতিটা করতে পারবেন") -> প্রায় আশি পঁচাশি পার্সেন্ট মানুষ ঢাকার বাইরে গ্রামে বাস করে এবং এই গ্রামের মানুষগুলো কিন্তু এতদিন পর্যন্ত তাদের বিশ্বাস ছিল বা এখনো পর্যন্ত টুছাম হছেন বিশ্বাস আছে যে করোনা হচ্ছে এটা শহরের অসু করানা হচ্ছে এটা বড় লোকের অসু তো আয় এখনো পর্যন্ত যদি একটা দেশের মানে এত বিশাল জনগোষ্ঠী করোনাকে ওভাবে শিকারী না করে তাহলে এই জনগোষ্ঠীকে আপনি কীভাবে আপনি সোশ্যাল ডিসটেন্সিংয়ের কথা বলেন আপনি মাস্ক পরার কথা বলেন এটা আপনি তো রাতারাতিটা করতে পারবেন | D2: =IFERROR(__xludf.DUMMYFUNCTION("""COMPUTED_VALUE"""),"No") -> No | E2: =IFERROR(__xludf.DUMMYFUNCTION("""COMPUTED_VALUE"""),"Yes") -> Yes | F2: =IFERROR(__xludf.DUMMYFUNCTION("""COMPUTED_VALUE"""),"Yes") -> Yes | G2: =IFERROR(__xludf.DUMMYFUNCTION("""COMPUTED_VALUE"""),0.5) -> 0.5 | H2: =IFERROR(__xludf.DUMMYFUNCTION("""COMPUTED_VALUE"""),0.5) -> 0.5 | I2: =IFERROR(__xludf.DUMMYFUNCTION("""COMPUTED_VALUE"""),1.0) -> 1 | J2: =IFERROR(__xludf.DUMMYFUNCTION("""COMPUTED_VALUE"""),1.0) -> 1 | K2: =IFERROR(__xludf.DUMMYFUNCTION("""COMPUTED_VALUE"""),"4– Usable, minor flaws Minor background noise.") -> 4– Usable, minor flaws Minor background noise. | L2: =IFERROR(__xludf.DUMMYFUNCTION("""COMPUTED_VALUE"""),"No") -> No
A3: =IFERROR(__xludf.DUMMYFUNCTION("""COMPUTED_VALUE"""),"collect\read\YouTube\Bangladesh Television (BTV)\__yFg8a8Zb4\02c8403f-16e9-441e-be80-669c2cf8de3e.flac") -> collect\read\YouTube\Bangladesh Television (BTV)\__yFg8a8Zb4\02c8403f-16e9-441e-be80-669c2cf8de3e.flac | B3: =IFERROR(__xludf.DUMMYFUNCTION("""COMPUTED_VALUE"""),30.0) -> 30 | C3: =IFERROR(__xludf.DUMMYFUNCTION("""COMPUTED_VALUE"""),"আমরা শুনেছি যো সেটা হয়তো আজকে আগামীকাল থেকে বা আজকে থেকেই হয়তো হয় শুরু হয়েছে এই ঠিকাদার প্রক্রিয়াটি এভাবে যদি টিকা দেয়ার প্রক্রিয়া আবার নতুন করে শুরু করা যায় এবং এটা যদি অব্যাহত রাখা যায় আমরা টিকার যোগান যদি আমরা পাই তবে একটি বিষয় মনে রাখতে হবে যে সারা বি"&"শ্বব্যাপী কিন্তু টিকার সংকট রয়েছে আপনি জানেন যে এখনো অনেক দেশ কিন্তু টিকার মুখই দেখে না ঠিকি ঠিক আছে এখানে পায় নাই আমাদের মত দেশ আমরা কিন্তু এ ব্যাপারে অনেক অগ্রগামী ছিলাম") -> আমরা শুনেছি যো সেটা হয়তো আজকে আগামীকাল থেকে বা আজকে থেকেই হয়তো হয় শুরু হয়েছে এই ঠিকাদার প্রক্রিয়াটি এভাবে যদি টিকা দেয়ার প্রক্রিয়া আবার নতুন করে শুরু করা যায় এবং এটা যদি অব্যাহত রাখা যায় আমরা টিকার যোগান যদি আমরা পাই তবে একটি বিষয় মনে রাখতে হবে যে সারা বিশ্বব্যাপী কিন্তু টিকার সংকট রয়েছে আপনি জানেন যে এখনো অনেক দেশ কিন্তু টিকার মুখই দেখে না ঠিকি ঠিক আছে এখানে পায় নাই আমাদের মত দেশ আমরা কিন্তু এ ব্যাপারে অনেক অগ্রগামী ছিলাম | D3: =IFERROR(__xludf.DUMMYFUNCTION("""COMPUTED_VALUE"""),"No") -> No | E3: =IFERROR(__xludf.DUMMYFUNCTION("""COMPUTED_VALUE"""),"No") -> No | F3: =IFERROR(__xludf.DUMMYFUNCTION("""COMPUTED_VALUE"""),"Yes") -> Yes | G3: =IFERROR(__xludf.DUMMYFUNCTION("""COMPUTED_VALUE"""),1.0) -> 1 | H3: =IFERROR(__xludf.DUMMYFUNCTION("""COMPUTED_VALUE"""),0.5) -> 0.5 | I3: =IFERROR(__xludf.DUMMYFUNCTION("""COMPUTED_VALUE"""),1.0) -> 1 | J3: =IFERROR(__xludf.DUMMYFUNCTION("""COMPUTED_VALUE"""),0.5) -> 0.5 | K3: =IFERROR(__xludf.DUMMYFUNCTION("""COMPUTED_VALUE"""),"4– Usable, minor flaws Minor background noise.") -> 4– Usable, minor flaws Minor background noise. | L3: =IFERROR(__xludf.DUMMYFUNCTION("""COMPUTED_VALUE"""),"No") -> No
A4: =IFERROR(__xludf.DUMMYFUNCTION("""COMPUTED_VALUE"""),"collect\read\YouTube\Bangladesh Television (BTV)\__yFg8a8Zb4\0537df13-c9ae-43da-9d40-b3a5ae3c7df1.flac") -> collect\read\YouTube\Bangladesh Television (BTV)\__yFg8a8Zb4\0537df13-c9ae-43da-9d40-b3a5ae3c7df1.flac | B4: =IFERROR(__xludf.DUMMYFUNCTION("""COMPUTED_VALUE"""),30.0) -> 30 | C4: =IFERROR(__xludf.DUMMYFUNCTION("""COMPUTED_VALUE"""),"বারবার বলেছিেন বিশ্ববাসীকে পৃথিবীতে কেউ একা বাঁচতে পারবে না সবাইকে নিয়ে বাঁচতে হবে সেই ক্ষেত্রে এই যে আপনার এই মেদাস্বত্ব আইনের যে জটিলতা সেটাকে আপনি কিভাবে দেখছেন আপনি যদি তিকি দুটো বাক্য শেষ করেন আমি হস্নে সকবা যদি উমি বিশেষ পরিস্থিতির কথা যদি বলি করোনা"&"র মতো এটাতে সারা পৃথিবীর মানুষ এখানে আমি কোনো মালিকানাসক্ত মেধা") -> বারবার বলেছিেন বিশ্ববাসীকে পৃথিবীতে কেউ একা বাঁচতে পারবে না সবাইকে নিয়ে বাঁচতে হবে সেই ক্ষেত্রে এই যে আপনার এই মেদাস্বত্ব আইনের যে জটিলতা সেটাকে আপনি কিভাবে দেখছেন আপনি যদি তিকি দুটো বাক্য শেষ করেন আমি হস্নে সকবা যদি উমি বিশেষ পরিস্থিতির কথা যদি বলি করোনার মতো এটাতে সারা পৃথিবীর মানুষ এখানে আমি কোনো মালিকানাসক্ত মেধা | D4: =IFERROR(__xludf.DUMMYFUNCTION("""COMPUTED_VALUE"""),"No") -> No | E4: =IFERROR(__xludf.DUMMYFUNCTION("""COMPUTED_VALUE"""),"Yes") -> Yes | F4: =IFERROR(__xludf.DUMMYFUNCTION("""COMPUTED_VALUE"""),"Yes") -> Yes | G4: =IFERROR(__xludf.DUMMYFUNCTION("""COMPUTED_VALUE"""),0.5) -> 0.5 | H4: =IFERROR(__xludf.DUMMYFUNCTION("""COMPUTED_VALUE"""),0.5) -> 0.5 | I4: =IFERROR(__xludf.DUMMYFUNCTION("""COMPUTED_VALUE"""),1.0) -> 1 | J4: =IFERROR(__xludf.DUMMYFUNCTION("""COMPUTED_VALUE"""),0.5) -> 0.5 | K4: =IFERROR(__xludf.DUMMYFUNCTION("""COMPUTED_VALUE"""),"2 - Poor quality Noisy, unclear,") -> 2 - Poor quality Noisy, unclear, | L4: =IFERROR(__xludf.DUMMYFUNCTION("""COMPUTED_VALUE"""),"No") -> No
A5: =IFERROR(__xludf.DUMMYFUNCTION("""COMPUTED_VALUE"""),"collect\read\YouTube\Bangladesh Television (BTV)\__yFg8a8Zb4\0bcedcfb-9679-4453-9c15-02688996cb63.flac") -> collect\read\YouTube\Bangladesh Television (BTV)\__yFg8a8Zb4\0bcedcfb-9679-4453-9c15-02688996cb63.flac | B5: =IFERROR(__xludf.DUMMYFUNCTION("""COMPUTED_VALUE"""),30.0) -> 30 | C5: =IFERROR(__xludf.DUMMYFUNCTION("""COMPUTED_VALUE"""),"হাস সেটাকে আমি কখনোই সমর্থন করিন করতে পারিনি এবং এটা বং সারা পৃথিবীতে মানবতাবাদী মানুষ কেউ সমর্থন অবশ্যই অবশ্য ইসমাইল খান আমিক শেষ পর্যায়ে আপনার কাছে জানতে চাই যে ট্রেড রিডেটেড আস্পেক্ট অ ইন্টেলেকচুয়াল প্রপার্টি রাইটস এই যে টিটসের কথাও আমি বলি তার কাউন্সি"&"ল পর্যন্ত এখনো পর্যন্ত আটকে আছে এই বিষয়টি আপনি খুব ভালো করে জানেন জে বাইডেন পর্যন্ত বেশ এক মাস চালিও বলেছে যে এই ব্যবস্থাপনা রোহিত করা দরকার কারণ মাননীয় প্রধানমন্ত্রী শেখ হাসিন") -> হাস সেটাকে আমি কখনোই সমর্থন করিন করতে পারিনি এবং এটা বং সারা পৃথিবীতে মানবতাবাদী মানুষ কেউ সমর্থন অবশ্যই অবশ্য ইসমাইল খান আমিক শেষ পর্যায়ে আপনার কাছে জানতে চাই যে ট্রেড রিডেটেড আস্পেক্ট অ ইন্টেলেকচুয়াল প্রপার্টি রাইটস এই যে টিটসের কথাও আমি বলি তার কাউন্সিল পর্যন্ত এখনো পর্যন্ত আটকে আছে এই বিষয়টি আপনি খুব ভালো করে জানেন জে বাইডেন পর্যন্ত বেশ এক মাস চালিও বলেছে যে এই ব্যবস্থাপনা রোহিত করা দরকার কারণ মাননীয় প্রধানমন্ত্রী শেখ হাসিন | D5: =IFERROR(__xludf.DUMMYFUNCTION("""COMPUTED_VALUE"""),"No") -> No | E5: =IFERROR(__xludf.DUMMYFUNCTION("""COMPUTED_VALUE"""),"Yes") -> Yes | F5: =IFERROR(__xludf.DUMMYFUNCTION("""COMPUTED_VALUE"""),"Yes") -> Yes | G5: =IFERROR(__xludf.DUMMYFUNCTION("""COMPUTED_VALUE"""),0.5) -> 0.5 | H5: =IFERROR(__xludf.DUMMYFUNCTION("""COMPUTED_VALUE"""),0.5) -> 0.5 | I5: =IFERROR(__xludf.DUMMYFUNCTION("""COMPUTED_VALUE"""),1.0) -> 1 | J5: =IFERROR(__xludf.DUMMYFUNCTION("""COMPUTED_VALUE"""),0.5) -> 0.5 | K5: =IFERROR(__xludf.DUMMYFUNCTION("""COMPUTED_VALUE"""),"3 – Mixed language or inconsistent quality") -> 3 – Mixed language or inconsistent quality | L5: =IFERROR(__xludf.DUMMYFUNCTION("""COMPUTED_VALUE"""),"Yes") -> Yes
A6: =IFERROR(__xludf.DUMMYFUNCTION("""COMPUTED_VALUE"""),"collect\read\YouTube\Bangladesh Television (BTV)\__yFg8a8Zb4\0be0a534-0e6e-4bbc-88be-4a62d2ac36af.flac") -> collect\read\YouTube\Bangladesh Television (BTV)\__yFg8a8Zb4\0be0a534-0e6e-4bbc-88be-4a62d2ac36af.flac | B6: =IFERROR(__xludf.DUMMYFUNCTION("""COMPUTED_VALUE"""),30.0) -> 30 | C6: =IFERROR(__xludf.DUMMYFUNCTION("""COMPUTED_VALUE"""),"ভাবী আমি ছাতে বছব যে তখন সাত্থের একজন মানুষ কভাবে এগিয়ে যাচ্ছেন আপনি এমডিযে কথা বলেছেন এমডিজে আটটা গোলের মধ্যে তিনটা গোলেই স্প্রুসিভলি আমাদের ছাত্র বিষয়ক রেটেড ছিল শিছু মৃত্যুহার কমানো মাতি মৃত্যু হার কমানো এবং মাি শাস্ত্র সমনত রাখা এবং ইনফ্েকটার ডিজিস যে"&"গুলো সারাবে এই বইের কন্ট্রোল করা এতিনটাতেই বাংলাদেশ আমাদের সান") -> ভাবী আমি ছাতে বছব যে তখন সাত্থের একজন মানুষ কভাবে এগিয়ে যাচ্ছেন আপনি এমডিযে কথা বলেছেন এমডিজে আটটা গোলের মধ্যে তিনটা গোলেই স্প্রুসিভলি আমাদের ছাত্র বিষয়ক রেটেড ছিল শিছু মৃত্যুহার কমানো মাতি মৃত্যু হার কমানো এবং মাি শাস্ত্র সমনত রাখা এবং ইনফ্েকটার ডিজিস যেগুলো সারাবে এই বইের কন্ট্রোল করা এতিনটাতেই বাংলাদেশ আমাদের সান | D6: =IFERROR(__xludf.DUMMYFUNCTION("""COMPUTED_VALUE"""),"No") -> No | E6: =IFERROR(__xludf.DUMMYFUNCTION("""COMPUTED_VALUE"""),"Yes") -> Yes | F6: =IFERROR(__xludf.DUMMYFUNCTION("""COMPUTED_VALUE"""),"Yes") -> Yes | G6: =IFERROR(__xludf.DUMMYFUNCTION("""COMPUTED_VALUE"""),0.5) -> 0.5 | H6: =IFERROR(__xludf.DUMMYFUNCTION("""COMPUTED_VALUE"""),0.5) -> 0.5 | I6: =IFERROR(__xludf.DUMMYFUNCTION("""COMPUTED_VALUE"""),1.0) -> 1 | J6: =IFERROR(__xludf.DUMMYFUNCTION("""COMPUTED_VALUE"""),0.5) -> 0.5 | K6: =IFERROR(__xludf.DUMMYFUNCTION("""COMPUTED_VALUE"""),"4– Usable, minor flaws Minor background noise.") -> 4– Usable, minor flaws Minor background noise. | L6: =IFERROR(__xludf.DUMMYFUNCTION("""COMPUTED_VALUE"""),"No") -> No
A7: =IFERROR(__xludf.DUMMYFUNCTION("""COMPUTED_VALUE"""),"collect\read\YouTube\Bangladesh Television (BTV)\__yFg8a8Zb4\0efe9120-ec50-4b37-b01a-4739cd0d63a9.flac") -> collect\read\YouTube\Bangladesh Television (BTV)\__yFg8a8Zb4\0efe9120-ec50-4b37-b01a-4739cd0d63a9.flac | B7: =IFERROR(__xludf.DUMMYFUNCTION("""COMPUTED_VALUE"""),30.0) -> 30 | C7: =IFERROR(__xludf.DUMMYFUNCTION("""COMPUTED_VALUE"""),"সেইক্ষেত্রে কিন্তু সবাই বলছেন আমিজাস্ট একটু এড করি সেটা তো অবশ্য একদিক থেকে ইকুইটির দিক থেকে চিন্তা করতে গেলে অবশ্যই আমরা মানে এটাকে রাইট হিসেবে আমাদের পাশটেক টিক থেকে এটা আমরা অবশ্যই রাইট বলে মনে করি যে এটিফার পেটেন্ট প্রাইট উন্মুক্ত করে দেয়া হোক এবং মান"&"ে দরিদ্র দেশগুলো যাদের সেই বিলিয়ন বিলিয়ন ডলার ইনভেস্ট করার ক্যাপাসিটি নায় তারাও যেন সেটারই পায় আমার আমার মনে হয় যে এদিকে মাননীয় প্রধানমন্ত্রীর যেই নেতৃত্ব এবং উনি যে যেভাবে উনি এটাকে পেশারাইজ করছেন আমার মনে হয় যে সেটা মানে আমাদের জন্য খুবই একটা") -> সেইক্ষেত্রে কিন্তু সবাই বলছেন আমিজাস্ট একটু এড করি সেটা তো অবশ্য একদিক থেকে ইকুইটির দিক থেকে চিন্তা করতে গেলে অবশ্যই আমরা মানে এটাকে রাইট হিসেবে আমাদের পাশটেক টিক থেকে এটা আমরা অবশ্যই রাইট বলে মনে করি যে এটিফার পেটেন্ট প্রাইট উন্মুক্ত করে দেয়া হোক এবং মানে দরিদ্র দেশগুলো যাদের সেই বিলিয়ন বিলিয়ন ডলার ইনভেস্ট করার ক্যাপাসিটি নায় তারাও যেন সেটারই পায় আমার আমার মনে হয় যে এদিকে মাননীয় প্রধানমন্ত্রীর যেই নেতৃত্ব এবং উনি যে যেভাবে উনি এটাকে পেশারাইজ করছেন আমার মনে হয় যে সেটা মানে আমাদের জন্য খুবই একটা | D7: =IFERROR(__xludf.DUMMYFUNCTION("""COMPUTED_VALUE"""),"No") -> No | E7: =IFERROR(__xludf.DUMMYFUNCTION("""COMPUTED_VALUE"""),"Yes") -> Yes | F7: =IFERROR(__xludf.DUMMYFUNCTION("""COMPUTED_VALUE"""),"Yes") -> Yes | G7: =IFERROR(__xludf.DUMMYFUNCTION("""COMPUTED_VALUE"""),0.5) -> 0.5 | H7: =IFERROR(__xludf.DUMMYFUNCTION("""COMPUTED_VALUE"""),0.5) -> 0.5 | I7: =IFERROR(__xludf.DUMMYFUNCTION("""COMPUTED_VALUE"""),0.5) -> 0.5 | J7: =IFERROR(__xludf.DUMMYFUNCTION("""COMPUTED_VALUE"""),0.5) -> 0.5 | K7: =IFERROR(__xludf.DUMMYFUNCTION("""COMPUTED_VALUE"""),"4– Usable, minor flaws Minor background noise.") -> 4– Usable, minor flaws Minor background noise. | L7: =IFERROR(__xludf.DUMMYFUNCTION("""COMPUTED_VALUE"""),"No") -> No
A8: =IFERROR(__xludf.DUMMYFUNCTION("""COMPUTED_VALUE"""),"collect\read\YouTube\Bangladesh Television (BTV)\__yFg8a8Zb4\14ccc579-631a-4976-88c9-1ca861f27432.flac") -> collect\read\YouTube\Bangladesh Television (BTV)\__yFg8a8Zb4\14ccc579-631a-4976-88c9-1ca861f27432.flac | B8: =IFERROR(__xludf.DUMMYFUNCTION("""COMPUTED_VALUE"""),30.0) -> 30 | C8: =IFERROR(__xludf.DUMMYFUNCTION("""COMPUTED_VALUE"""),"বলে আমরা কিন্তু অনেক ভালো অবস্থা আছি আমাদের এখানে করোনা ব্যবস্থাপনা প্রথম দিকে হয়তো একটু সমস্যা আমাদের ছিল কিন্তু পরবর্তীতে কিন্তু আমাদের সীমিত সামর্থ্য নিয়েও আমরা কিন্তু যেমন ভাবে এগিয়ে যাচ্ছি মাননীয় প্রধানমন্ত্রীর নেতৃত্বে সেটা কিন্তু অবশ্যই সারা বিশ্ব "&"বিশ্বব্যাপী ভূয়সী প্রশংসিত হয়েছে এবং আমরা তার ফল পাচ্ছি তো মাননীয় প্রধানমন্ত্রী যে কথাটি সংসদে বলেছেন যে আমাদের করোনা ব্যবস্থাপনায় স্বাস্থ্যবিধি মেনে চলা এই কথাটি কিন্তু আমাদেরকে অক্ষর অক্ষর পালন পার্লন যদি") -> বলে আমরা কিন্তু অনেক ভালো অবস্থা আছি আমাদের এখানে করোনা ব্যবস্থাপনা প্রথম দিকে হয়তো একটু সমস্যা আমাদের ছিল কিন্তু পরবর্তীতে কিন্তু আমাদের সীমিত সামর্থ্য নিয়েও আমরা কিন্তু যেমন ভাবে এগিয়ে যাচ্ছি মাননীয় প্রধানমন্ত্রীর নেতৃত্বে সেটা কিন্তু অবশ্যই সারা বিশ্ব বিশ্বব্যাপী ভূয়সী প্রশংসিত হয়েছে এবং আমরা তার ফল পাচ্ছি তো মাননীয় প্রধানমন্ত্রী যে কথাটি সংসদে বলেছেন যে আমাদের করোনা ব্যবস্থাপনায় স্বাস্থ্যবিধি মেনে চলা এই কথাটি কিন্তু আমাদেরকে অক্ষর অক্ষর পালন পার্লন যদি | D8: =IFERROR(__xludf.DUMMYFUNCTION("""COMPUTED_VALUE"""),"Yes") -> Yes | E8: =IFERROR(__xludf.DUMMYFUNCTION("""COMPUTED_VALUE"""),"No") -> No | F8: =IFERROR(__xludf.DUMMYFUNCTION("""COMPUTED_VALUE"""),"No") -> No | G8: =IFERROR(__xludf.DUMMYFUNCTION("""COMPUTED_VALUE"""),1.0) -> 1 | H8: =IFERROR(__xludf.DUMMYFUNCTION("""COMPUTED_VALUE"""),1.0) -> 1 | I8: =IFERROR(__xludf.DUMMYFUNCTION("""COMPUTED_VALUE"""),1.0) -> 1 | J8: =IFERROR(__xludf.DUMMYFUNCTION("""COMPUTED_VALUE"""),1.0) -> 1 | K8: =IFERROR(__xludf.DUMMYFUNCTION("""COMPUTED_VALUE"""),"4– Usable, minor flaws Minor background noise.") -> 4– Usable, minor flaws Minor background noise. | L8: =IFERROR(__xludf.DUMMYFUNCTION("""COMPUTED_VALUE"""),"No") -> No
A9: =IFERROR(__xludf.DUMMYFUNCTION("""COMPUTED_VALUE"""),"collect\read\YouTube\Bangladesh Television (BTV)\__yFg8a8Zb4\1e60b7f8-1be0-472d-9f0a-1c3bcc6e526f.flac") -> collect\read\YouTube\Bangladesh Television (BTV)\__yFg8a8Zb4\1e60b7f8-1be0-472d-9f0a-1c3bcc6e526f.flac | B9: =IFERROR(__xludf.DUMMYFUNCTION("""COMPUTED_VALUE"""),30.0) -> 30 | C9: =IFERROR(__xludf.DUMMYFUNCTION("""COMPUTED_VALUE"""),"সেই আলোচনা আমরা আসবো অধ্যাপক ইসমাইল খান গত পঁশচ সাতক্ষীরাতে সংক্রমণের হার ছিল তিপ্পান্ন দশমিক এক নয় শতাংশ তা আমরা যদি বলছি সীমান্ত লাগোয়ার যে ব্যাপারটি বলছি আপনি একটা বিশ্লেষণ চমৎকার করেছেন যে আমর তারাতো যদি সংক্রমণ কম হয়ে থাকে আর ওই চাঁপাইনবাবগঞ্জের লাগ"&"োয়া রাজ্যে ভারতের যে রাজ্য খেরাপ যদি সংক্রমণ") -> সেই আলোচনা আমরা আসবো অধ্যাপক ইসমাইল খান গত পঁশচ সাতক্ষীরাতে সংক্রমণের হার ছিল তিপ্পান্ন দশমিক এক নয় শতাংশ তা আমরা যদি বলছি সীমান্ত লাগোয়ার যে ব্যাপারটি বলছি আপনি একটা বিশ্লেষণ চমৎকার করেছেন যে আমর তারাতো যদি সংক্রমণ কম হয়ে থাকে আর ওই চাঁপাইনবাবগঞ্জের লাগোয়া রাজ্যে ভারতের যে রাজ্য খেরাপ যদি সংক্রমণ | D9: =IFERROR(__xludf.DUMMYFUNCTION("""COMPUTED_VALUE"""),"No") -> No | E9: =IFERROR(__xludf.DUMMYFUNCTION("""COMPUTED_VALUE"""),"No") -> No | F9: =IFERROR(__xludf.DUMMYFUNCTION("""COMPUTED_VALUE"""),"Yes") -> Yes | G9: =IFERROR(__xludf.DUMMYFUNCTION("""COMPUTED_VALUE"""),1.0) -> 1 | H9: =IFERROR(__xludf.DUMMYFUNCTION("""COMPUTED_VALUE"""),0.5) -> 0.5 | I9: =IFERROR(__xludf.DUMMYFUNCTION("""COMPUTED_VALUE"""),1.0) -> 1 | J9: =IFERROR(__xludf.DUMMYFUNCTION("""COMPUTED_VALUE"""),1.0) -> 1 | K9: =IFERROR(__xludf.DUMMYFUNCTION("""COMPUTED_VALUE"""),"4– Usable, minor flaws Minor background noise.") -> 4– Usable, minor flaws Minor background noise. | L9: =IFERROR(__xludf.DUMMYFUNCTION("""COMPUTED_VALUE"""),"No") -> No
A10: =IFERROR(__xludf.DUMMYFUNCTION("""COMPUTED_VALUE"""),"collect\read\YouTube\Bangladesh Television (BTV)\__yFg8a8Zb4\2cb5aceb-cb8e-46c9-b56e-acc70f034da1.flac") -> collect\read\YouTube\Bangladesh Television (BTV)\__yFg8a8Zb4\2cb5aceb-cb8e-46c9-b56e-acc70f034da1.flac | B10: =IFERROR(__xludf.DUMMYFUNCTION("""COMPUTED_VALUE"""),30.0) -> 30 | C10: =IFERROR(__xludf.DUMMYFUNCTION("""COMPUTED_VALUE"""),"না করি তাহলে কিন্তু আমাদের অনেক সামনে অনেক বিপদ আসতে পারে কারণ আপনি জানেন যে বর্তমানে যে ইন্ডিয়ান ভ্যারিয়েন্ট আমাদের এখানে এসেছে সে ইন্ডিয়ান ভ্যারিয়েন্টের কারণে আমাদের পেরিফারি থেকে শুরু করে কিন্তু একটা ঢাকার দিকে আসতে আস্তে আস্তে করে তো এক্ষেত্রে আমরা আগ"&"ে থেকেই জানি যে স্বাস্থ্যবিধি মেইন্টেন করার ব্যাপার আমাদের ভিতরে কিন্তু উদাসীনতা আছে মাননীয় প্রধানমন্ত্রী বারংবার যখনই কথা বলেছেন তখনই কিন্তু এই বিষয়টির উপর গুরুত্ব দিয়েছেন কিন্তু আমাদের জনগণকে কিন্তু আমরা সেটা সেভাবে কিন্তু আমরা আ স্বাস্থ্যবিধি মানার ব্য"&"াপারে") -> না করি তাহলে কিন্তু আমাদের অনেক সামনে অনেক বিপদ আসতে পারে কারণ আপনি জানেন যে বর্তমানে যে ইন্ডিয়ান ভ্যারিয়েন্ট আমাদের এখানে এসেছে সে ইন্ডিয়ান ভ্যারিয়েন্টের কারণে আমাদের পেরিফারি থেকে শুরু করে কিন্তু একটা ঢাকার দিকে আসতে আস্তে আস্তে করে তো এক্ষেত্রে আমরা আগে থেকেই জানি যে স্বাস্থ্যবিধি মেইন্টেন করার ব্যাপার আমাদের ভিতরে কিন্তু উদাসীনতা আছে মাননীয় প্রধানমন্ত্রী বারংবার যখনই কথা বলেছেন তখনই কিন্তু এই বিষয়টির উপর গুরুত্ব দিয়েছেন কিন্তু আমাদের জনগণকে কিন্তু আমরা সেটা সেভাবে কিন্তু আমরা আ স্বাস্থ্যবিধি মানার ব্যাপারে | D10: =IFERROR(__xludf.DUMMYFUNCTION("""COMPUTED_VALUE"""),"No") -> No | E10: =IFERROR(__xludf.DUMMYFUNCTION("""COMPUTED_VALUE"""),"Yes") -> Yes | F10: =IFERROR(__xludf.DUMMYFUNCTION("""COMPUTED_VALUE"""),"Yes") -> Yes | G10: =IFERROR(__xludf.DUMMYFUNCTION("""COMPUTED_VALUE"""),0.5) -> 0.5 | H10: =IFERROR(__xludf.DUMMYFUNCTION("""COMPUTED_VALUE"""),0.5) -> 0.5 | I10: =IFERROR(__xludf.DUMMYFUNCTION("""COMPUTED_VALUE"""),1.0) -> 1 | J10: =IFERROR(__xludf.DUMMYFUNCTION("""COMPUTED_VALUE"""),0.5) -> 0.5 | K10: =IFERROR(__xludf.DUMMYFUNCTION("""COMPUTED_VALUE"""),"4– Usable, minor flaws Minor background noise.") -> 4– Usable, minor flaws Minor background noise. | L10: =IFERROR(__xludf.DUMMYFUNCTION("""COMPUTED_VALUE"""),"No") -> No
A11: =IFERROR(__xludf.DUMMYFUNCTION("""COMPUTED_VALUE"""),"collect\read\YouTube\Bangladesh Television (BTV)\__yFg8a8Zb4\2e92e8dd-747f-4132-840d-53d505fed6a5.flac") -> collect\read\YouTube\Bangladesh Television (BTV)\__yFg8a8Zb4\2e92e8dd-747f-4132-840d-53d505fed6a5.flac | B11: =IFERROR(__xludf.DUMMYFUNCTION("""COMPUTED_VALUE"""),30.0) -> 30 | C11: =IFERROR(__xludf.DUMMYFUNCTION("""COMPUTED_VALUE"""),"মানে রিসেন্টকে রিট্রেক্ট করতে হয়েছে তাদের এ বিশ্ব সংস্থা থেকে বলেছে যে এই পিতাগুলো তারা ফিরিয়ে নিত এখন এই যে তারা রিস্ট নিল ধনী দেশগুলো বা উন্নত দেশগুলো যে রিস্ট নিল এটাকে তো তারা তাদের তো এটা রাইট আছে আমি আমি এই পাঁচ প্রেক্রিট থেকে দেখতে চাই যে তাদের অবশ"&"্যই রাইট আছে ডিফিশান নেয়া যে তারা এটাকে কি করবে কি ড সদ্দিকে এখন রিশ্বে যখন মহামারী ছড়ে যায়েই তখন সরশিষ্ট নাগরিকত্ সকলেরই অধিকার আছে তার জীবন বাঁচানোর") -> মানে রিসেন্টকে রিট্রেক্ট করতে হয়েছে তাদের এ বিশ্ব সংস্থা থেকে বলেছে যে এই পিতাগুলো তারা ফিরিয়ে নিত এখন এই যে তারা রিস্ট নিল ধনী দেশগুলো বা উন্নত দেশগুলো যে রিস্ট নিল এটাকে তো তারা তাদের তো এটা রাইট আছে আমি আমি এই পাঁচ প্রেক্রিট থেকে দেখতে চাই যে তাদের অবশ্যই রাইট আছে ডিফিশান নেয়া যে তারা এটাকে কি করবে কি ড সদ্দিকে এখন রিশ্বে যখন মহামারী ছড়ে যায়েই তখন সরশিষ্ট নাগরিকত্ সকলেরই অধিকার আছে তার জীবন বাঁচানোর | D11: =IFERROR(__xludf.DUMMYFUNCTION("""COMPUTED_VALUE"""),"No") -> No | E11: =IFERROR(__xludf.DUMMYFUNCTION("""COMPUTED_VALUE"""),"Yes") -> Yes | F11: =IFERROR(__xludf.DUMMYFUNCTION("""COMPUTED_VALUE"""),"Yes") -> Yes | G11: =IFERROR(__xludf.DUMMYFUNCTION("""COMPUTED_VALUE"""),0.5) -> 0.5 | H11: =IFERROR(__xludf.DUMMYFUNCTION("""COMPUTED_VALUE"""),0.5) -> 0.5 | I11: =IFERROR(__xludf.DUMMYFUNCTION("""COMPUTED_VALUE"""),0.5) -> 0.5 | J11: =IFERROR(__xludf.DUMMYFUNCTION("""COMPUTED_VALUE"""),0.5) -> 0.5 | K11: =IFERROR(__xludf.DUMMYFUNCTION("""COMPUTED_VALUE"""),"4– Usable, minor flaws Minor background noise.") -> 4– Usable, minor flaws Minor background noise. | L11: =IFERROR(__xludf.DUMMYFUNCTION("""COMPUTED_VALUE"""),"No") -> No
A12: =IFERROR(__xludf.DUMMYFUNCTION("""COMPUTED_VALUE"""),"collect\read\YouTube\Bangladesh Television (BTV)\__yFg8a8Zb4\2e9f155a-24ef-4f76-b008-33dcfeeca3e4.flac") -> collect\read\YouTube\Bangladesh Television (BTV)\__yFg8a8Zb4\2e9f155a-24ef-4f76-b008-33dcfeeca3e4.flac | B12: =IFERROR(__xludf.DUMMYFUNCTION("""COMPUTED_VALUE"""),30.0) -> 30 | C12: =IFERROR(__xludf.DUMMYFUNCTION("""COMPUTED_VALUE"""),"আইনকে ছাড় দিতে হবে এবং কারিগরি যে জ্ঞান সেই জ্ঞানকে আমাদের সবার কাজে লাগাতে হবে এবং তাহলে বাংলাদেশ ভ্যাকসিন উৎপাদনে অবশ্য সক্ষম একটি জাতি এটা কোনো মালিকানা থাকতে পারবে না এখন জুইসেভেন্ড মক্ত দেশগুলোর নেতৃবৃন্দ কন্তু তার সুরে সু মুলাচ্ছেন পতিক কিন্তু দুঃখক"&"োন ঘটনা ডক্তার মাহবুব সিদ্দিকীও বলবেন প্রফেসর রহমানে বলবেন যে সারা পৃথিবীতে এখনো পর্যন্ত মাত্র তেরো শতাংশ কি চৌদ্দ শতাংশ") -> আইনকে ছাড় দিতে হবে এবং কারিগরি যে জ্ঞান সেই জ্ঞানকে আমাদের সবার কাজে লাগাতে হবে এবং তাহলে বাংলাদেশ ভ্যাকসিন উৎপাদনে অবশ্য সক্ষম একটি জাতি এটা কোনো মালিকানা থাকতে পারবে না এখন জুইসেভেন্ড মক্ত দেশগুলোর নেতৃবৃন্দ কন্তু তার সুরে সু মুলাচ্ছেন পতিক কিন্তু দুঃখকোন ঘটনা ডক্তার মাহবুব সিদ্দিকীও বলবেন প্রফেসর রহমানে বলবেন যে সারা পৃথিবীতে এখনো পর্যন্ত মাত্র তেরো শতাংশ কি চৌদ্দ শতাংশ | D12: =IFERROR(__xludf.DUMMYFUNCTION("""COMPUTED_VALUE"""),"No") -> No | E12: =IFERROR(__xludf.DUMMYFUNCTION("""COMPUTED_VALUE"""),"Yes") -> Yes | F12: =IFERROR(__xludf.DUMMYFUNCTION("""COMPUTED_VALUE"""),"Yes") -> Yes | G12: =IFERROR(__xludf.DUMMYFUNCTION("""COMPUTED_VALUE"""),0.5) -> 0.5 | H12: =IFERROR(__xludf.DUMMYFUNCTION("""COMPUTED_VALUE"""),0.5) -> 0.5 | I12: =IFERROR(__xludf.DUMMYFUNCTION("""COMPUTED_VALUE"""),0.5) -> 0.5 | J12: =IFERROR(__xludf.DUMMYFUNCTION("""COMPUTED_VALUE"""),0.5) -> 0.5 | K12: =IFERROR(__xludf.DUMMYFUNCTION("""COMPUTED_VALUE"""),"4– Usable, minor flaws Minor background noise.") -> 4– Usable, minor flaws Minor background noise. | L12: =IFERROR(__xludf.DUMMYFUNCTION("""COMPUTED_VALUE"""),"No") -> No
A13: =IFERROR(__xludf.DUMMYFUNCTION("""COMPUTED_VALUE"""),"collect\read\YouTube\Bangladesh Television (BTV)\__yFg8a8Zb4\30ddb972-c5ef-4017-b585-0d0ba7e59950.flac") -> collect\read\YouTube\Bangladesh Television (BTV)\__yFg8a8Zb4\30ddb972-c5ef-4017-b585-0d0ba7e59950.flac | B13: =IFERROR(__xludf.DUMMYFUNCTION("""COMPUTED_VALUE"""),30.0) -> 30 | C13: =IFERROR(__xludf.DUMMYFUNCTION("""COMPUTED_VALUE"""),"এই কে মেতা পৃথিবী যেখানে যাই হোক না কেন এখানে ওই সবগুলো রোহিত করে পৃথিবীর সবাই যাতে বেঁচে থাকার ব্যাপারে এখানে ওইজ কোন বিপ্রণছি একজম হিউম্যানিস্টিক ভিউ থেকে আমি এটা টরম বিরুদ্ধী এবং যেটা বলছেন সেটা একদম এটা যাতে সারা পৃথিবীর মানুষ এই জিনিসটা এই অবস্থায় যা"&"তে আপনাকে অসকে ধন্যবাদ আে ধন্যবাদ আইতো প্রথান মুক্তি করেছে") -> এই কে মেতা পৃথিবী যেখানে যাই হোক না কেন এখানে ওই সবগুলো রোহিত করে পৃথিবীর সবাই যাতে বেঁচে থাকার ব্যাপারে এখানে ওইজ কোন বিপ্রণছি একজম হিউম্যানিস্টিক ভিউ থেকে আমি এটা টরম বিরুদ্ধী এবং যেটা বলছেন সেটা একদম এটা যাতে সারা পৃথিবীর মানুষ এই জিনিসটা এই অবস্থায় যাতে আপনাকে অসকে ধন্যবাদ আে ধন্যবাদ আইতো প্রথান মুক্তি করেছে | D13: =IFERROR(__xludf.DUMMYFUNCTION("""COMPUTED_VALUE"""),"No") -> No | E13: =IFERROR(__xludf.DUMMYFUNCTION("""COMPUTED_VALUE"""),"Yes") -> Yes | F13: =IFERROR(__xludf.DUMMYFUNCTION("""COMPUTED_VALUE"""),"Yes") -> Yes | G13: =IFERROR(__xludf.DUMMYFUNCTION("""COMPUTED_VALUE"""),0.5) -> 0.5 | H13: =IFERROR(__xludf.DUMMYFUNCTION("""COMPUTED_VALUE"""),0.5) -> 0.5 | I13: =IFERROR(__xludf.DUMMYFUNCTION("""COMPUTED_VALUE"""),0.5) -> 0.5 | J13: =IFERROR(__xludf.DUMMYFUNCTION("""COMPUTED_VALUE"""),0.5) -> 0.5 | K13: =IFERROR(__xludf.DUMMYFUNCTION("""COMPUTED_VALUE"""),"4– Usable, minor flaws Minor background noise.") -> 4– Usable, minor flaws Minor background noise. | L13: =IFERROR(__xludf.DUMMYFUNCTION("""COMPUTED_VALUE"""),"No") -> No
A14: =IFERROR(__xludf.DUMMYFUNCTION("""COMPUTED_VALUE"""),"collect\read\YouTube\Bangladesh Television (BTV)\__yFg8a8Zb4\33e4dee4-015c-40f8-9b56-1a03d2b290ac.flac") -> collect\read\YouTube\Bangladesh Television (BTV)\__yFg8a8Zb4\33e4dee4-015c-40f8-9b56-1a03d2b290ac.flac | B14: =IFERROR(__xludf.DUMMYFUNCTION("""COMPUTED_VALUE"""),30.0) -> 30 | C14: =IFERROR(__xludf.DUMMYFUNCTION("""COMPUTED_VALUE"""),"আপনার খেয়াল আছে নিশ্চয়ই বা দেশকয়েছে নিশ্চয়ই জানি যে যে ডায়রিয়ার ওষুধ ওষুধ হিসেবে আমরা খাবার স্যালাইন খাওয়ানো এবং সিমপলি টয়লেট করার পরে হাত ধোয়া এই জিনিসটা শেখাতে কিন্তু আমাদের রাষ্ট্রযন্ত্র যতটুকু আছে মিডিয়ার পুরো সবসমন্বিত উদ্যোগ নিয়েও কিন্তু আমাদের প্রা"&"য় এক দুই দশক লেগে গিয়েছে এই এই জিনিসটা মানুষকে বোঝাতে যে টয়লেটের পরে হাত ধুতে হয় সেই জায়গায় যে যখন কেমি পিপায়ার ছিল না সেখানে হঠাৎ করে করোনার মতো একটা পেন্ডেমিক আসলো হয়তো এর") -> আপনার খেয়াল আছে নিশ্চয়ই বা দেশকয়েছে নিশ্চয়ই জানি যে যে ডায়রিয়ার ওষুধ ওষুধ হিসেবে আমরা খাবার স্যালাইন খাওয়ানো এবং সিমপলি টয়লেট করার পরে হাত ধোয়া এই জিনিসটা শেখাতে কিন্তু আমাদের রাষ্ট্রযন্ত্র যতটুকু আছে মিডিয়ার পুরো সবসমন্বিত উদ্যোগ নিয়েও কিন্তু আমাদের প্রায় এক দুই দশক লেগে গিয়েছে এই এই জিনিসটা মানুষকে বোঝাতে যে টয়লেটের পরে হাত ধুতে হয় সেই জায়গায় যে যখন কেমি পিপায়ার ছিল না সেখানে হঠাৎ করে করোনার মতো একটা পেন্ডেমিক আসলো হয়তো এর | D14: =IFERROR(__xludf.DUMMYFUNCTION("""COMPUTED_VALUE"""),"No") -> No | E14: =IFERROR(__xludf.DUMMYFUNCTION("""COMPUTED_VALUE"""),"Yes") -> Yes | F14: =IFERROR(__xludf.DUMMYFUNCTION("""COMPUTED_VALUE"""),"Yes") -> Yes | G14: =IFERROR(__xludf.DUMMYFUNCTION("""COMPUTED_VALUE"""),0.5) -> 0.5 | H14: =IFERROR(__xludf.DUMMYFUNCTION("""COMPUTED_VALUE"""),0.5) -> 0.5 | I14: =IFERROR(__xludf.DUMMYFUNCTION("""COMPUTED_VALUE"""),0.5) -> 0.5 | J14: =IFERROR(__xludf.DUMMYFUNCTION("""COMPUTED_VALUE"""),0.5) -> 0.5 | K14: =IFERROR(__xludf.DUMMYFUNCTION("""COMPUTED_VALUE"""),"4– Usable, minor flaws Minor background noise.") -> 4– Usable, minor flaws Minor background noise. | L14: =IFERROR(__xludf.DUMMYFUNCTION("""COMPUTED_VALUE"""),"No") -> No
A15: =IFERROR(__xludf.DUMMYFUNCTION("""COMPUTED_VALUE"""),"collect\read\YouTube\Bangladesh Television (BTV)\__yFg8a8Zb4\3691c46f-2183-4896-afef-5252e1be60a6.flac") -> collect\read\YouTube\Bangladesh Television (BTV)\__yFg8a8Zb4\3691c46f-2183-4896-afef-5252e1be60a6.flac | B15: =IFERROR(__xludf.DUMMYFUNCTION("""COMPUTED_VALUE"""),30.0) -> 30 | C15: =IFERROR(__xludf.DUMMYFUNCTION("""COMPUTED_VALUE"""),"ব্যাপারে আপনার বিশ্বেষণটে কি আমরা কেন পারছি না এই দুরত্ব বিধিমানা কিংবা সং্গনিরধ বাস্তবায়ন করা ইটোয়া ব্যা পারে আপনার অভিমতটা কি একজন অণুজীব বিজ্ঞানী হিসেবে জি থ্যাংক ইউ আমাকে কি শোনা যাচ্ছে এখন আছে ঠিক আছে ধন্যবাদ তার প্রথম কথা হচ্ছে যে আমাদের দেশের যে চ্"&"যালেঞ্জ স্বাস্থ্য ব্যবস্থার যে মানে পলিসিগুলো আছে এগলে ইমপ্লিমেন্টেশনটা কিন্তু আমাদের চেয়ে চ্যালেঞ্জটা একটু রিফ্রেন্ টাইপে যেমন আপনি খেয়াল করে দেখবেন যে বাংলাদেশ") -> ব্যাপারে আপনার বিশ্বেষণটে কি আমরা কেন পারছি না এই দুরত্ব বিধিমানা কিংবা সং্গনিরধ বাস্তবায়ন করা ইটোয়া ব্যা পারে আপনার অভিমতটা কি একজন অণুজীব বিজ্ঞানী হিসেবে জি থ্যাংক ইউ আমাকে কি শোনা যাচ্ছে এখন আছে ঠিক আছে ধন্যবাদ তার প্রথম কথা হচ্ছে যে আমাদের দেশের যে চ্যালেঞ্জ স্বাস্থ্য ব্যবস্থার যে মানে পলিসিগুলো আছে এগলে ইমপ্লিমেন্টেশনটা কিন্তু আমাদের চেয়ে চ্যালেঞ্জটা একটু রিফ্রেন্ টাইপে যেমন আপনি খেয়াল করে দেখবেন যে বাংলাদেশ | D15: =IFERROR(__xludf.DUMMYFUNCTION("""COMPUTED_VALUE"""),"No") -> No | E15: =IFERROR(__xludf.DUMMYFUNCTION("""COMPUTED_VALUE"""),"Yes") -> Yes | F15: =IFERROR(__xludf.DUMMYFUNCTION("""COMPUTED_VALUE"""),"Yes") -> Yes | G15: =IFERROR(__xludf.DUMMYFUNCTION("""COMPUTED_VALUE"""),0.5) -> 0.5 | H15: =IFERROR(__xludf.DUMMYFUNCTION("""COMPUTED_VALUE"""),0.5) -> 0.5 | I15: =IFERROR(__xludf.DUMMYFUNCTION("""COMPUTED_VALUE"""),1.0) -> 1 | J15: =IFERROR(__xludf.DUMMYFUNCTION("""COMPUTED_VALUE"""),0.5) -> 0.5 | K15: =IFERROR(__xludf.DUMMYFUNCTION("""COMPUTED_VALUE"""),"4– Usable, minor flaws Minor background noise.") -> 4– Usable, minor flaws Minor background noise. | L15: =IFERROR(__xludf.DUMMYFUNCTION("""COMPUTED_VALUE"""),"No") -> No
A16: =IFERROR(__xludf.DUMMYFUNCTION("""COMPUTED_VALUE"""),"collect\read\YouTube\Bangladesh Television (BTV)\__yFg8a8Zb4\37038c53-54e3-4e9b-a906-4418719f49a7.flac") -> collect\read\YouTube\Bangladesh Television (BTV)\__yFg8a8Zb4\37038c53-54e3-4e9b-a906-4418719f49a7.flac | B16: =IFERROR(__xludf.DUMMYFUNCTION("""COMPUTED_VALUE"""),30.0) -> 30 | C16: =IFERROR(__xludf.DUMMYFUNCTION("""COMPUTED_VALUE"""),"ব বারবার মনুর পর্তমান বলেছেন এক্সিলিচিয়ান প্রিটমেন্ট বা জাট সুটি হোক না কেন আমরা যে বিধিবিধান আছে আমরা যাতে আত্মলিতে না ভুলি যাতে ওই জ আমাদেরকে নিজেকে প্রোটেট করায় সমাজকে প্রটেট করা যে বিটিনিজ ক দিয়ে দিয়ে দেখিয় দিয়েছেন আর কত্য দেখা বেসেগুলো যাতে আমরা মেনে"&" চরি মাস্ক ফর দু নবাদ দোয়া ধনা আমি একজন সিনিয়র ফার্মাসিস্ট") -> ব বারবার মনুর পর্তমান বলেছেন এক্সিলিচিয়ান প্রিটমেন্ট বা জাট সুটি হোক না কেন আমরা যে বিধিবিধান আছে আমরা যাতে আত্মলিতে না ভুলি যাতে ওই জ আমাদেরকে নিজেকে প্রোটেট করায় সমাজকে প্রটেট করা যে বিটিনিজ ক দিয়ে দিয়ে দেখিয় দিয়েছেন আর কত্য দেখা বেসেগুলো যাতে আমরা মেনে চরি মাস্ক ফর দু নবাদ দোয়া ধনা আমি একজন সিনিয়র ফার্মাসিস্ট | D16: =IFERROR(__xludf.DUMMYFUNCTION("""COMPUTED_VALUE"""),"No") -> No | E16: =IFERROR(__xludf.DUMMYFUNCTION("""COMPUTED_VALUE"""),"No") -> No | F16: =IFERROR(__xludf.DUMMYFUNCTION("""COMPUTED_VALUE"""),"No") -> No | G16: =IFERROR(__xludf.DUMMYFUNCTION("""COMPUTED_VALUE"""),0.0) -> 0 | H16: =IFERROR(__xludf.DUMMYFUNCTION("""COMPUTED_VALUE"""),0.5) -> 0.5 | I16: =IFERROR(__xludf.DUMMYFUNCTION("""COMPUTED_VALUE"""),0.5) -> 0.5 | J16: =IFERROR(__xludf.DUMMYFUNCTION("""COMPUTED_VALUE"""),0.5) -> 0.5 | K16: =IFERROR(__xludf.DUMMYFUNCTION("""COMPUTED_VALUE"""),"4– Usable, minor flaws Minor background noise.") -> 4– Usable, minor flaws Minor background noise. | L16: =IFERROR(__xludf.DUMMYFUNCTION("""COMPUTED_VALUE"""),"No") -> No
A17: =IFERROR(__xludf.DUMMYFUNCTION("""COMPUTED_VALUE"""),"collect\read\YouTube\Bangladesh Television (BTV)\__yFg8a8Zb4\3b976163-381e-449c-871c-17ea92ada33d.flac") -> collect\read\YouTube\Bangladesh Television (BTV)\__yFg8a8Zb4\3b976163-381e-449c-871c-17ea92ada33d.flac | B17: =IFERROR(__xludf.DUMMYFUNCTION("""COMPUTED_VALUE"""),30.0) -> 30 | C17: =IFERROR(__xludf.DUMMYFUNCTION("""COMPUTED_VALUE"""),"কেউ হললে অল ফর হেম এভরি ওয়ান এবনি সোসাইটি এমনি সব সমাজের সবাই একটা চিলিৎ কাজ করতে হবে সেটা এবার করোনায় আমি এই জায়গাটায় আপনাকে একটু থামিয়ে ডাক্তার সিদ্দিকীর কাছে আসতে চায় কাজ সিদ্দিকী অফেসর ইসমাইল খান যেখানে শেষ করলেন এই সবার জন্য স্বাস্থ্য যে প্রেক্ষাপটটা"&" তুলে ধরলেন এবং পরবর্তীতে তিনি যে বললেন এসকে সমন্বিত ব্যবস্থাপনা কথা বললেন") -> কেউ হললে অল ফর হেম এভরি ওয়ান এবনি সোসাইটি এমনি সব সমাজের সবাই একটা চিলিৎ কাজ করতে হবে সেটা এবার করোনায় আমি এই জায়গাটায় আপনাকে একটু থামিয়ে ডাক্তার সিদ্দিকীর কাছে আসতে চায় কাজ সিদ্দিকী অফেসর ইসমাইল খান যেখানে শেষ করলেন এই সবার জন্য স্বাস্থ্য যে প্রেক্ষাপটটা তুলে ধরলেন এবং পরবর্তীতে তিনি যে বললেন এসকে সমন্বিত ব্যবস্থাপনা কথা বললেন | D17: =IFERROR(__xludf.DUMMYFUNCTION("""COMPUTED_VALUE"""),"No") -> No | E17: =IFERROR(__xludf.DUMMYFUNCTION("""COMPUTED_VALUE"""),"No") -> No | F17: =IFERROR(__xludf.DUMMYFUNCTION("""COMPUTED_VALUE"""),"No") -> No | G17: =IFERROR(__xludf.DUMMYFUNCTION("""COMPUTED_VALUE"""),0.5) -> 0.5 | H17: =IFERROR(__xludf.DUMMYFUNCTION("""COMPUTED_VALUE"""),0.5) -> 0.5 | I17: =IFERROR(__xludf.DUMMYFUNCTION("""COMPUTED_VALUE"""),1.0) -> 1 | J17: =IFERROR(__xludf.DUMMYFUNCTION("""COMPUTED_VALUE"""),0.5) -> 0.5 | K17: =IFERROR(__xludf.DUMMYFUNCTION("""COMPUTED_VALUE"""),"4– Usable, minor flaws Minor background noise.") -> 4– Usable, minor flaws Minor background noise. | L17: =IFERROR(__xludf.DUMMYFUNCTION("""COMPUTED_VALUE"""),"No") -> No
A18: =IFERROR(__xludf.DUMMYFUNCTION("""COMPUTED_VALUE"""),"collect\read\YouTube\Bangladesh Television (BTV)\__yFg8a8Zb4\4292f9e9-1abf-437c-a34f-63e512e34e6a.flac") -> collect\read\YouTube\Bangladesh Television (BTV)\__yFg8a8Zb4\4292f9e9-1abf-437c-a34f-63e512e34e6a.flac | B18: =IFERROR(__xludf.DUMMYFUNCTION("""COMPUTED_VALUE"""),30.0) -> 30 | C18: =IFERROR(__xludf.DUMMYFUNCTION("""COMPUTED_VALUE"""),"ফ্রিয়েন্ট ছড়িয়ে থাকে যেটার ইনফেকটিভিটি অত বেশি না সেক্ষেত্রে কিন্তু এই এই বিষয়টা হতে পারে কিন্তু এক সপ্তা আছে আমি একটা একটা বিষয় আপটার কাছে উঠবে উপস্থাপন করে যাই পরে নিশ্চয়ই ব্যাখ্যায় আসবো আমরা গত এক সপ্তাহ আগে চাঁপাইনবাবগঞ্জে যে সংক্রমণের হার ছিল সেটা কি"&"ন্তু গত পরশু আমার কমে এসেছে মানে এগুলোর অনেকগুলো পর্যবেক্ষণ আছে অধ্যাপনকে ইসমাইল খান নিশ্চয় আপনি ডক্তার মাবুদ সিদ্দিকীর কথাগুলো শুনছি লেম আমার সথে আমারও বলি") -> ফ্রিয়েন্ট ছড়িয়ে থাকে যেটার ইনফেকটিভিটি অত বেশি না সেক্ষেত্রে কিন্তু এই এই বিষয়টা হতে পারে কিন্তু এক সপ্তা আছে আমি একটা একটা বিষয় আপটার কাছে উঠবে উপস্থাপন করে যাই পরে নিশ্চয়ই ব্যাখ্যায় আসবো আমরা গত এক সপ্তাহ আগে চাঁপাইনবাবগঞ্জে যে সংক্রমণের হার ছিল সেটা কিন্তু গত পরশু আমার কমে এসেছে মানে এগুলোর অনেকগুলো পর্যবেক্ষণ আছে অধ্যাপনকে ইসমাইল খান নিশ্চয় আপনি ডক্তার মাবুদ সিদ্দিকীর কথাগুলো শুনছি লেম আমার সথে আমারও বলি | D18: =IFERROR(__xludf.DUMMYFUNCTION("""COMPUTED_VALUE"""),"No") -> No | E18: =IFERROR(__xludf.DUMMYFUNCTION("""COMPUTED_VALUE"""),"No") -> No | F18: =IFERROR(__xludf.DUMMYFUNCTION("""COMPUTED_VALUE"""),"Yes") -> Yes | G18: =IFERROR(__xludf.DUMMYFUNCTION("""COMPUTED_VALUE"""),0.5) -> 0.5 | H18: =IFERROR(__xludf.DUMMYFUNCTION("""COMPUTED_VALUE"""),0.5) -> 0.5 | I18: =IFERROR(__xludf.DUMMYFUNCTION("""COMPUTED_VALUE"""),0.0) -> 0 | J18: =IFERROR(__xludf.DUMMYFUNCTION("""COMPUTED_VALUE"""),0.5) -> 0.5 | K18: =IFERROR(__xludf.DUMMYFUNCTION("""COMPUTED_VALUE"""),"4– Usable, minor flaws Minor background noise.") -> 4– Usable, minor flaws Minor background noise. | L18: =IFERROR(__xludf.DUMMYFUNCTION("""COMPUTED_VALUE"""),"No") -> No
A19: =IFERROR(__xludf.DUMMYFUNCTION("""COMPUTED_VALUE"""),"collect\read\YouTube\Bangladesh Television (BTV)\__yFg8a8Zb4\42df9076-0a40-4d05-a70b-d94d21698972.flac") -> collect\read\YouTube\Bangladesh Television (BTV)\__yFg8a8Zb4\42df9076-0a40-4d05-a70b-d94d21698972.flac | B19: =IFERROR(__xludf.DUMMYFUNCTION("""COMPUTED_VALUE"""),30.0) -> 30 | C19: =IFERROR(__xludf.DUMMYFUNCTION("""COMPUTED_VALUE"""),"কাটেরিয়ার বিসিসে টেস্ট করছেন আমার মনে হয় ছে এটা একটা কালচারাল আস্পেক্ট আছে পর ইসেপল কোনো একটা এলাকার মধ্যে যদি অনেক সময় আমরা জানি যে রুমার অথবা হুলো প্যানিক বলেন যাই কিছু বলেন না কেন এই জিনিসগুলো যখন ছড়িয়ে যায় তখন কিন্তু দলে দলে ঝাঁকে ঝাঁকে সব মানুষ হয়তো "&"আতঙ্কিত হয়ে পড়ে আমরা জানি যে এই সময়টা কিন্তু সিজন অফ ফ্লুয়েরো সিজন ততেব আপনি খেয়াল করে দেখবেন যে শুধু যে জানা টেস্ট করাচ্ছে তাদের শুধু যে করোনা আর করোনায় পাওয়া যাচ্ছে তা না করোনা ছাড়া অনেক আপনার সংক্রমণ ভাইরাসও কিন্তু আছে তো সেই ক্ষেত্রে কোন একটা এলাকার ম"&"ধ্যে") -> কাটেরিয়ার বিসিসে টেস্ট করছেন আমার মনে হয় ছে এটা একটা কালচারাল আস্পেক্ট আছে পর ইসেপল কোনো একটা এলাকার মধ্যে যদি অনেক সময় আমরা জানি যে রুমার অথবা হুলো প্যানিক বলেন যাই কিছু বলেন না কেন এই জিনিসগুলো যখন ছড়িয়ে যায় তখন কিন্তু দলে দলে ঝাঁকে ঝাঁকে সব মানুষ হয়তো আতঙ্কিত হয়ে পড়ে আমরা জানি যে এই সময়টা কিন্তু সিজন অফ ফ্লুয়েরো সিজন ততেব আপনি খেয়াল করে দেখবেন যে শুধু যে জানা টেস্ট করাচ্ছে তাদের শুধু যে করোনা আর করোনায় পাওয়া যাচ্ছে তা না করোনা ছাড়া অনেক আপনার সংক্রমণ ভাইরাসও কিন্তু আছে তো সেই ক্ষেত্রে কোন একটা এলাকার মধ্যে | D19: =IFERROR(__xludf.DUMMYFUNCTION("""COMPUTED_VALUE"""),"No") -> No | E19: =IFERROR(__xludf.DUMMYFUNCTION("""COMPUTED_VALUE"""),"Yes") -> Yes | F19: =IFERROR(__xludf.DUMMYFUNCTION("""COMPUTED_VALUE"""),"Yes") -> Yes | G19: =IFERROR(__xludf.DUMMYFUNCTION("""COMPUTED_VALUE"""),0.5) -> 0.5 | H19: =IFERROR(__xludf.DUMMYFUNCTION("""COMPUTED_VALUE"""),0.5) -> 0.5 | I19: =IFERROR(__xludf.DUMMYFUNCTION("""COMPUTED_VALUE"""),0.5) -> 0.5 | J19: =IFERROR(__xludf.DUMMYFUNCTION("""COMPUTED_VALUE"""),0.5) -> 0.5 | K19: =IFERROR(__xludf.DUMMYFUNCTION("""COMPUTED_VALUE"""),"4– Usable, minor flaws Minor background noise.") -> 4– Usable, minor flaws Minor background noise. | L19: =IFERROR(__xludf.DUMMYFUNCTION("""COMPUTED_VALUE"""),"No") -> No
A20: =IFERROR(__xludf.DUMMYFUNCTION("""COMPUTED_VALUE"""),"collect\read\YouTube\Bangladesh Television (BTV)\__yFg8a8Zb4\45dcfbd7-6354-439e-9023-9587de8ce046.flac") -> collect\read\YouTube\Bangladesh Television (BTV)\__yFg8a8Zb4\45dcfbd7-6354-439e-9023-9587de8ce046.flac | B20: =IFERROR(__xludf.DUMMYFUNCTION("""COMPUTED_VALUE"""),30.0) -> 30 | C20: =IFERROR(__xludf.DUMMYFUNCTION("""COMPUTED_VALUE"""),"যে জেলাগুলি সেখানে আবার দেখা গেছে তো সেখানে আবার আমরা ব্যবস্থা নিচ্ছি কিন্তু আমি সবাইকে বলব যে আমাদের স্বাস্থ্য বিধিটার জন্য সকলে মেনে চলেন এটাই বাংলাদেশের সব মানুষের কাছে আমার একটা আহ্বান থাকবে আমরা জিকা দান থেকে শুরু করে সবরকম ব্যবস্থা আমরা নিচ্ছি তারপর"&"ও নিজেরা সুরক্ষিত থাকতে হবে এটাই চাই অধ্যাপক ডাক্তার এসএম আব্দুর রহমান মাননীয় প্রধানমন্ত্রীর বক্তব্যের অংশটুকু আমরা দেখলাম") -> যে জেলাগুলি সেখানে আবার দেখা গেছে তো সেখানে আবার আমরা ব্যবস্থা নিচ্ছি কিন্তু আমি সবাইকে বলব যে আমাদের স্বাস্থ্য বিধিটার জন্য সকলে মেনে চলেন এটাই বাংলাদেশের সব মানুষের কাছে আমার একটা আহ্বান থাকবে আমরা জিকা দান থেকে শুরু করে সবরকম ব্যবস্থা আমরা নিচ্ছি তারপরও নিজেরা সুরক্ষিত থাকতে হবে এটাই চাই অধ্যাপক ডাক্তার এসএম আব্দুর রহমান মাননীয় প্রধানমন্ত্রীর বক্তব্যের অংশটুকু আমরা দেখলাম | D20: =IFERROR(__xludf.DUMMYFUNCTION("""COMPUTED_VALUE"""),"No") -> No | E20: =IFERROR(__xludf.DUMMYFUNCTION("""COMPUTED_VALUE"""),"No") -> No | F20: =IFERROR(__xludf.DUMMYFUNCTION("""COMPUTED_VALUE"""),"Yes") -> Yes | G20: =IFERROR(__xludf.DUMMYFUNCTION("""COMPUTED_VALUE"""),0.5) -> 0.5 | H20: =IFERROR(__xludf.DUMMYFUNCTION("""COMPUTED_VALUE"""),0.5) -> 0.5 | I20: =IFERROR(__xludf.DUMMYFUNCTION("""COMPUTED_VALUE"""),0.5) -> 0.5 | J20: =IFERROR(__xludf.DUMMYFUNCTION("""COMPUTED_VALUE"""),0.5) -> 0.5 | K20: =IFERROR(__xludf.DUMMYFUNCTION("""COMPUTED_VALUE"""),"4– Usable, minor flaws Minor background noise.") -> 4– Usable, minor flaws Minor background noise. | L20: =IFERROR(__xludf.DUMMYFUNCTION("""COMPUTED_VALUE"""),"No") -> No
A21: =IFERROR(__xludf.DUMMYFUNCTION("""COMPUTED_VALUE"""),"collect\read\YouTube\Bangladesh Television (BTV)\__yFg8a8Zb4\543065f8-038a-448a-af42-02a8cd7289f9.flac") -> collect\read\YouTube\Bangladesh Television (BTV)\__yFg8a8Zb4\543065f8-038a-448a-af42-02a8cd7289f9.flac | B21: =IFERROR(__xludf.DUMMYFUNCTION("""COMPUTED_VALUE"""),30.0) -> 30 | C21: =IFERROR(__xludf.DUMMYFUNCTION("""COMPUTED_VALUE"""),"নানে একজন মানুষ কীভাবে চলবে আদের ব্যাংক একাউন্টে কিন্তু সরকারের পক্ষ থেকে টাকা চলে গিয়েছে রেগুলার বেসিসে চলে গিয়েছে এটা আমাদের এখানে অসম্ভব ইমপ্রেকটিক্যাল তো যে কারণে আমাদের এই দরিদ্র জনগোষ্ঠী বা প্রান্তিক জনগোষ্ঠীকে কিন্তু তাদের মোবিলিটি মেইন্টেইন করতে হ"&"বে আর করোনার ক্ষেত্রে একটা সবচেয়ে বড় চ্যালেঞ্জ হল আমরা সেই গত বছর থেকেই জানি যে সিমটোম্যাটিক কেসের চেয়ে অ্যাসিম্টোমাটিক কেস অনেক ক্ষেত্রে অনেক বেশি হয় এবং আমাদের কমিউনিটির মধ্যে যারা আছে তাদের মধ্যে বেশ কিছু মানুষ থাকে সুপার স্প্রেডার এটা ইসমাইল খান স্যার") -> নানে একজন মানুষ কীভাবে চলবে আদের ব্যাংক একাউন্টে কিন্তু সরকারের পক্ষ থেকে টাকা চলে গিয়েছে রেগুলার বেসিসে চলে গিয়েছে এটা আমাদের এখানে অসম্ভব ইমপ্রেকটিক্যাল তো যে কারণে আমাদের এই দরিদ্র জনগোষ্ঠী বা প্রান্তিক জনগোষ্ঠীকে কিন্তু তাদের মোবিলিটি মেইন্টেইন করতে হবে আর করোনার ক্ষেত্রে একটা সবচেয়ে বড় চ্যালেঞ্জ হল আমরা সেই গত বছর থেকেই জানি যে সিমটোম্যাটিক কেসের চেয়ে অ্যাসিম্টোমাটিক কেস অনেক ক্ষেত্রে অনেক বেশি হয় এবং আমাদের কমিউনিটির মধ্যে যারা আছে তাদের মধ্যে বেশ কিছু মানুষ থাকে সুপার স্প্রেডার এটা ইসমাইল খান স্যার | D21: =IFERROR(__xludf.DUMMYFUNCTION("""COMPUTED_VALUE"""),"No") -> No | E21: =IFERROR(__xludf.DUMMYFUNCTION("""COMPUTED_VALUE"""),"Yes") -> Yes | F21: =IFERROR(__xludf.DUMMYFUNCTION("""COMPUTED_VALUE"""),"Yes") -> Yes | G21: =IFERROR(__xludf.DUMMYFUNCTION("""COMPUTED_VALUE"""),1.0) -> 1 | H21: =IFERROR(__xludf.DUMMYFUNCTION("""COMPUTED_VALUE"""),1.0) -> 1 | I21: =IFERROR(__xludf.DUMMYFUNCTION("""COMPUTED_VALUE"""),1.0) -> 1 | J21: =IFERROR(__xludf.DUMMYFUNCTION("""COMPUTED_VALUE"""),0.5) -> 0.5 | K21: =IFERROR(__xludf.DUMMYFUNCTION("""COMPUTED_VALUE"""),"4– Usable, minor flaws Minor background noise.") -> 4– Usable, minor flaws Minor background noise. | L21: =IFERROR(__xludf.DUMMYFUNCTION("""COMPUTED_VALUE"""),"No") -> No
A22: =IFERROR(__xludf.DUMMYFUNCTION("""COMPUTED_VALUE"""),"collect\read\YouTube\Bangladesh Television (BTV)\__yFg8a8Zb4\66c3a0ff-2f66-4d9f-885f-84b31693920a.flac") -> collect\read\YouTube\Bangladesh Television (BTV)\__yFg8a8Zb4\66c3a0ff-2f66-4d9f-885f-84b31693920a.flac | B22: =IFERROR(__xludf.DUMMYFUNCTION("""COMPUTED_VALUE"""),30.0) -> 30 | C22: =IFERROR(__xludf.DUMMYFUNCTION("""COMPUTED_VALUE"""),"যে শেষ পর্যন্ত ব্রাহ্মণবাড়িয়ার অবস্থা কি হয় আমার কেন যেন মনে হয় যে অলরেডি ব্রাহ্মণবাড়িয়ে এসেে যে বিষয়টি আলোচনা হচ্ছে আসলো টিকার যে সংকট আমি মনে করি যে মাননীয় প্রধানমন্ত্রী যেটা বলেছেন যে টিকার মেধাস্বত্ব আইন যদি এটা মোহিত করা হয় তাহলে এখন যে মহামারী আমাদে"&"র চলছে অবশ্যই যারা টিকা উৎপাদন করেছেন টিকা নিয়ে গবেষণা করেছেন তারা শ্রম দিয়েছেন তারা অর্থ খরচ করেছেন তারা ব্যবসা করবেন ব্যবসা করতে কোনো বাধা নেই কিন্তু ব্যবসা তো") -> যে শেষ পর্যন্ত ব্রাহ্মণবাড়িয়ার অবস্থা কি হয় আমার কেন যেন মনে হয় যে অলরেডি ব্রাহ্মণবাড়িয়ে এসেে যে বিষয়টি আলোচনা হচ্ছে আসলো টিকার যে সংকট আমি মনে করি যে মাননীয় প্রধানমন্ত্রী যেটা বলেছেন যে টিকার মেধাস্বত্ব আইন যদি এটা মোহিত করা হয় তাহলে এখন যে মহামারী আমাদের চলছে অবশ্যই যারা টিকা উৎপাদন করেছেন টিকা নিয়ে গবেষণা করেছেন তারা শ্রম দিয়েছেন তারা অর্থ খরচ করেছেন তারা ব্যবসা করবেন ব্যবসা করতে কোনো বাধা নেই কিন্তু ব্যবসা তো | D22: =IFERROR(__xludf.DUMMYFUNCTION("""COMPUTED_VALUE"""),"No") -> No | E22: =IFERROR(__xludf.DUMMYFUNCTION("""COMPUTED_VALUE"""),"No") -> No | F22: =IFERROR(__xludf.DUMMYFUNCTION("""COMPUTED_VALUE"""),"No") -> No | G22: =IFERROR(__xludf.DUMMYFUNCTION("""COMPUTED_VALUE"""),0.5) -> 0.5 | H22: =IFERROR(__xludf.DUMMYFUNCTION("""COMPUTED_VALUE"""),0.5) -> 0.5 | I22: =IFERROR(__xludf.DUMMYFUNCTION("""COMPUTED_VALUE"""),0.5) -> 0.5 | J22: =IFERROR(__xludf.DUMMYFUNCTION("""COMPUTED_VALUE"""),0.5) -> 0.5 | K22: =IFERROR(__xludf.DUMMYFUNCTION("""COMPUTED_VALUE"""),"4– Usable, minor flaws Minor background noise.") -> 4– Usable, minor flaws Minor background noise. | L22: =IFERROR(__xludf.DUMMYFUNCTION("""COMPUTED_VALUE"""),"No") -> No
A23: =IFERROR(__xludf.DUMMYFUNCTION("""COMPUTED_VALUE"""),"collect\read\YouTube\Bangladesh Television (BTV)\__yFg8a8Zb4\712b88e2-182d-4983-8732-da48035cf95c.flac") -> collect\read\YouTube\Bangladesh Television (BTV)\__yFg8a8Zb4\712b88e2-182d-4983-8732-da48035cf95c.flac | B23: =IFERROR(__xludf.DUMMYFUNCTION("""COMPUTED_VALUE"""),30.0) -> 30 | C23: =IFERROR(__xludf.DUMMYFUNCTION("""COMPUTED_VALUE"""),"যমন মোবালিটি অত বেশি হবে ততই যদি ঐ ক্যারিয়ার যুদ্ধ হইয়া থাকে ইনফ্যেকশার হয়ে থাকে আোন্ড আনোন্ডায় সেযুগ ইনফ্রথ হয়ে থাকে মবিরি যত বেশি ে সিভাবে ছড়াবে ব্রাহ্মণবাড়িয়ার কথা যে আপনি বলেছেন ব্রাহ্মণ বাড়িয়ে কিন্তু ত্রিপুরারের চেয়ে পঝাযে আর চাপাননমন্ট ওদিকে যে ভারত"&"ের যে জেলাগুলো আছে এমনিে কর কি কয়েছে এমনতো বা কী ওদিকে যে জেলাগুলো সেগুলোতে কিন্তু") -> যমন মোবালিটি অত বেশি হবে ততই যদি ঐ ক্যারিয়ার যুদ্ধ হইয়া থাকে ইনফ্যেকশার হয়ে থাকে আোন্ড আনোন্ডায় সেযুগ ইনফ্রথ হয়ে থাকে মবিরি যত বেশি ে সিভাবে ছড়াবে ব্রাহ্মণবাড়িয়ার কথা যে আপনি বলেছেন ব্রাহ্মণ বাড়িয়ে কিন্তু ত্রিপুরারের চেয়ে পঝাযে আর চাপাননমন্ট ওদিকে যে ভারতের যে জেলাগুলো আছে এমনিে কর কি কয়েছে এমনতো বা কী ওদিকে যে জেলাগুলো সেগুলোতে কিন্তু | D23: =IFERROR(__xludf.DUMMYFUNCTION("""COMPUTED_VALUE"""),"No") -> No | E23: =IFERROR(__xludf.DUMMYFUNCTION("""COMPUTED_VALUE"""),"Yes") -> Yes | F23: =IFERROR(__xludf.DUMMYFUNCTION("""COMPUTED_VALUE"""),"Yes") -> Yes | G23: =IFERROR(__xludf.DUMMYFUNCTION("""COMPUTED_VALUE"""),0.0) -> 0 | H23: =IFERROR(__xludf.DUMMYFUNCTION("""COMPUTED_VALUE"""),0.0) -> 0 | I23: =IFERROR(__xludf.DUMMYFUNCTION("""COMPUTED_VALUE"""),0.0) -> 0 | J23: =IFERROR(__xludf.DUMMYFUNCTION("""COMPUTED_VALUE"""),0.5) -> 0.5 | K23: =IFERROR(__xludf.DUMMYFUNCTION("""COMPUTED_VALUE"""),"4– Usable, minor flaws Minor background noise.") -> 4– Usable, minor flaws Minor background noise. | L23: =IFERROR(__xludf.DUMMYFUNCTION("""COMPUTED_VALUE"""),"No") -> No
A24: =IFERROR(__xludf.DUMMYFUNCTION("""COMPUTED_VALUE"""),"collect\read\YouTube\Bangladesh Television (BTV)\__yFg8a8Zb4\7293edc4-655e-496e-81fa-9232473be93f.flac") -> collect\read\YouTube\Bangladesh Television (BTV)\__yFg8a8Zb4\7293edc4-655e-496e-81fa-9232473be93f.flac | B24: =IFERROR(__xludf.DUMMYFUNCTION("""COMPUTED_VALUE"""),30.0) -> 30 | C24: =IFERROR(__xludf.DUMMYFUNCTION("""COMPUTED_VALUE"""),"এর সাংসদ এশিয়ার মধ্যে অবশ্যই এবং সারা পৃথিবীতে উল্লেখযোগ্য প্রভার্ট পভার্টি এবং অন্য কিছু ইন্ডিক্রেটের করে আপনাই ভালো জানেন আমাদের দ্বস্ভাই জান আমি করা না বলে শুধু স্বাস্থ্র ইযেগুলো ইনডিকরেটডমূলক আমরা অবার বিত্র সাফল্য অর্জন করেছি এবং সারা বিশ্বের কাছে আ"&"মরা এমডিডি অর্জনে ঐ লক্ষ্যমাত্র টার যে সীমা ছিল তার আইডি অর্জনে আমরা মাননীয় প্রধানমন্ত্রীর নেতৃত্বে আমরা ছাড়া বিজেবিতা প্রর্জিত হয়েছি তারপরে সাতসিটেবলি এভেল প বলে ডি এমজিনি") -> এর সাংসদ এশিয়ার মধ্যে অবশ্যই এবং সারা পৃথিবীতে উল্লেখযোগ্য প্রভার্ট পভার্টি এবং অন্য কিছু ইন্ডিক্রেটের করে আপনাই ভালো জানেন আমাদের দ্বস্ভাই জান আমি করা না বলে শুধু স্বাস্থ্র ইযেগুলো ইনডিকরেটডমূলক আমরা অবার বিত্র সাফল্য অর্জন করেছি এবং সারা বিশ্বের কাছে আমরা এমডিডি অর্জনে ঐ লক্ষ্যমাত্র টার যে সীমা ছিল তার আইডি অর্জনে আমরা মাননীয় প্রধানমন্ত্রীর নেতৃত্বে আমরা ছাড়া বিজেবিতা প্রর্জিত হয়েছি তারপরে সাতসিটেবলি এভেল প বলে ডি এমজিনি | D24: =IFERROR(__xludf.DUMMYFUNCTION("""COMPUTED_VALUE"""),"No") -> No | E24: =IFERROR(__xludf.DUMMYFUNCTION("""COMPUTED_VALUE"""),"Yes") -> Yes | F24: =IFERROR(__xludf.DUMMYFUNCTION("""COMPUTED_VALUE"""),"Yes") -> Yes | G24: =IFERROR(__xludf.DUMMYFUNCTION("""COMPUTED_VALUE"""),0.5) -> 0.5 | H24: =IFERROR(__xludf.DUMMYFUNCTION("""COMPUTED_VALUE"""),0.5) -> 0.5 | I24: =IFERROR(__xludf.DUMMYFUNCTION("""COMPUTED_VALUE"""),0.5) -> 0.5 | J24: =IFERROR(__xludf.DUMMYFUNCTION("""COMPUTED_VALUE"""),0.5) -> 0.5 | K24: =IFERROR(__xludf.DUMMYFUNCTION("""COMPUTED_VALUE"""),"4– Usable, minor flaws Minor background noise.") -> 4– Usable, minor flaws Minor background noise. | L24: =IFERROR(__xludf.DUMMYFUNCTION("""COMPUTED_VALUE"""),"No") -> No
A25: =IFERROR(__xludf.DUMMYFUNCTION("""COMPUTED_VALUE"""),"collect\read\YouTube\Bangladesh Television (BTV)\__yFg8a8Zb4\76593329-5a94-4b3a-aa04-5df11fc8190a.flac") -> collect\read\YouTube\Bangladesh Television (BTV)\__yFg8a8Zb4\76593329-5a94-4b3a-aa04-5df11fc8190a.flac | B25: =IFERROR(__xludf.DUMMYFUNCTION("""COMPUTED_VALUE"""),30.0) -> 30 | C25: =IFERROR(__xludf.DUMMYFUNCTION("""COMPUTED_VALUE"""),"অনেক চন্ত ওও করোনার হাার পচি মবি সেটা কিন্তু অনেক বেশি তিপনু এখানে ত্রিপুরা রাইজ যে করোনা কন্ত্ এতটা বেশি না সুতরাং আপনি যে সীমান্তমন্ত্রী কথা বলছেন সীবনরবতা হলেই তো সুতা হবে না ওই পার্ছে মানুষের মোমিনিটি এবং ওই পার্ছে যে কটি রকম করণা ইনফ্যাক্টিভ অধ্যাপক "&"ডক্টর এয়াসএম আব্দুর রহমান কি বলেন এক্ষেত্রে অরথাৎ ইসমাইল খন আপনার কাছে ফিরে আসছি ধন্যবাদ আপনাকে আমি মনে করি যে হট স্পট নিয়ে যে বিষয়টি যে") -> অনেক চন্ত ওও করোনার হাার পচি মবি সেটা কিন্তু অনেক বেশি তিপনু এখানে ত্রিপুরা রাইজ যে করোনা কন্ত্ এতটা বেশি না সুতরাং আপনি যে সীমান্তমন্ত্রী কথা বলছেন সীবনরবতা হলেই তো সুতা হবে না ওই পার্ছে মানুষের মোমিনিটি এবং ওই পার্ছে যে কটি রকম করণা ইনফ্যাক্টিভ অধ্যাপক ডক্টর এয়াসএম আব্দুর রহমান কি বলেন এক্ষেত্রে অরথাৎ ইসমাইল খন আপনার কাছে ফিরে আসছি ধন্যবাদ আপনাকে আমি মনে করি যে হট স্পট নিয়ে যে বিষয়টি যে | D25: =IFERROR(__xludf.DUMMYFUNCTION("""COMPUTED_VALUE"""),"No") -> No | E25: =IFERROR(__xludf.DUMMYFUNCTION("""COMPUTED_VALUE"""),"Yes") -> Yes | F25: =IFERROR(__xludf.DUMMYFUNCTION("""COMPUTED_VALUE"""),"Yes") -> Yes | G25: =IFERROR(__xludf.DUMMYFUNCTION("""COMPUTED_VALUE"""),0.0) -> 0 | H25: =IFERROR(__xludf.DUMMYFUNCTION("""COMPUTED_VALUE"""),0.5) -> 0.5 | I25: =IFERROR(__xludf.DUMMYFUNCTION("""COMPUTED_VALUE"""),0.5) -> 0.5 | J25: =IFERROR(__xludf.DUMMYFUNCTION("""COMPUTED_VALUE"""),0.5) -> 0.5 | K25: =IFERROR(__xludf.DUMMYFUNCTION("""COMPUTED_VALUE"""),"4– Usable, minor flaws Minor background noise.") -> 4– Usable, minor flaws Minor background noise. | L25: =IFERROR(__xludf.DUMMYFUNCTION("""COMPUTED_VALUE"""),"No") -> No
A26: =IFERROR(__xludf.DUMMYFUNCTION("""COMPUTED_VALUE"""),"collect\read\YouTube\Bangladesh Television (BTV)\__yFg8a8Zb4\7d00aaa5-a538-4df8-b451-77a985466426.flac") -> collect\read\YouTube\Bangladesh Television (BTV)\__yFg8a8Zb4\7d00aaa5-a538-4df8-b451-77a985466426.flac | B26: =IFERROR(__xludf.DUMMYFUNCTION("""COMPUTED_VALUE"""),30.0) -> 30 | C26: =IFERROR(__xludf.DUMMYFUNCTION("""COMPUTED_VALUE"""),"সুন্দরভাবে এবং কোনো নির্ঝন যাটা কোনো ধরনের কোনো অসুবিধার সহকারী কিন্তু টিকা প্রদান সম্ভব হয়েছে দুর্ভাগ্যবশত আমাদের টিকা আমরা সেরাম ইনস্টিটিউট থেকে না পাওয়ার কারণে হয়তো টিকা আমরা টিকাদান প্রক্রিয়াটি আমরা চলমান রাখতে পারেনি কিন্তু যে বিষয়টা আপনি বললেন যে জু"&"লাই থেকে আবার নতুন করে টিকা দান শুরু হবে এটা খুবই আশার সংবাদ আমি মনে করি আমাদের এই টিকাদান প্রক্রিয়া আবার এটা যদি শুরু হয় এবং এটা যদি চলতে থাকে") -> সুন্দরভাবে এবং কোনো নির্ঝন যাটা কোনো ধরনের কোনো অসুবিধার সহকারী কিন্তু টিকা প্রদান সম্ভব হয়েছে দুর্ভাগ্যবশত আমাদের টিকা আমরা সেরাম ইনস্টিটিউট থেকে না পাওয়ার কারণে হয়তো টিকা আমরা টিকাদান প্রক্রিয়াটি আমরা চলমান রাখতে পারেনি কিন্তু যে বিষয়টা আপনি বললেন যে জুলাই থেকে আবার নতুন করে টিকা দান শুরু হবে এটা খুবই আশার সংবাদ আমি মনে করি আমাদের এই টিকাদান প্রক্রিয়া আবার এটা যদি শুরু হয় এবং এটা যদি চলতে থাকে | D26: =IFERROR(__xludf.DUMMYFUNCTION("""COMPUTED_VALUE"""),"No") -> No | E26: =IFERROR(__xludf.DUMMYFUNCTION("""COMPUTED_VALUE"""),"No") -> No | F26: =IFERROR(__xludf.DUMMYFUNCTION("""COMPUTED_VALUE"""),"Yes") -> Yes | G26: =IFERROR(__xludf.DUMMYFUNCTION("""COMPUTED_VALUE"""),1.0) -> 1 | H26: =IFERROR(__xludf.DUMMYFUNCTION("""COMPUTED_VALUE"""),0.5) -> 0.5 | I26: =IFERROR(__xludf.DUMMYFUNCTION("""COMPUTED_VALUE"""),0.5) -> 0.5 | J26: =IFERROR(__xludf.DUMMYFUNCTION("""COMPUTED_VALUE"""),0.5) -> 0.5 | K26: =IFERROR(__xludf.DUMMYFUNCTION("""COMPUTED_VALUE"""),"4– Usable, minor flaws Minor background noise.") -> 4– Usable, minor flaws Minor background noise. | L26: =IFERROR(__xludf.DUMMYFUNCTION("""COMPUTED_VALUE"""),"No") -> No
A27: =IFERROR(__xludf.DUMMYFUNCTION("""COMPUTED_VALUE"""),"collect\read\YouTube\Bangladesh Television (BTV)\__yFg8a8Zb4\7f1867ae-752c-4f47-a8ec-2e79dba628d6.flac") -> collect\read\YouTube\Bangladesh Television (BTV)\__yFg8a8Zb4\7f1867ae-752c-4f47-a8ec-2e79dba628d6.flac | B27: =IFERROR(__xludf.DUMMYFUNCTION("""COMPUTED_VALUE"""),30.0) -> 30 | C27: =IFERROR(__xludf.DUMMYFUNCTION("""COMPUTED_VALUE"""),"প্রধানমন্ত্রীর সুনির্দিষ্ট পরিকল্পনা ও দূরদর্শী নেতৃত্বে বাংলাদেশ অপ্রতিরোধ্য গতিতে এগিয়ে যাচ্ছে বাজেট আলোচনায় বললেন সংসদ সদস্যরা বিএনপির রাজনীতি এদেশের রাজনৈতিক সহাবস্থানের পথে বড় অন্তরায় মন্তব্য ওবায়দুল কাদেরে বিশ্ববিদ্যালয়গুলো শুধু উন্নত শিক্ষাই দিবে ন"&"া উন্নত মানুষও গড়ে তুলবে তথ্য ও সম্প্রচারমন্ত্রী ডক্টর হাছান মাহমুদের আশাবাদ করোনাভাইরাসের দেশে আরো") -> প্রধানমন্ত্রীর সুনির্দিষ্ট পরিকল্পনা ও দূরদর্শী নেতৃত্বে বাংলাদেশ অপ্রতিরোধ্য গতিতে এগিয়ে যাচ্ছে বাজেট আলোচনায় বললেন সংসদ সদস্যরা বিএনপির রাজনীতি এদেশের রাজনৈতিক সহাবস্থানের পথে বড় অন্তরায় মন্তব্য ওবায়দুল কাদেরে বিশ্ববিদ্যালয়গুলো শুধু উন্নত শিক্ষাই দিবে না উন্নত মানুষও গড়ে তুলবে তথ্য ও সম্প্রচারমন্ত্রী ডক্টর হাছান মাহমুদের আশাবাদ করোনাভাইরাসের দেশে আরো | D27: =IFERROR(__xludf.DUMMYFUNCTION("""COMPUTED_VALUE"""),"No") -> No | E27: =IFERROR(__xludf.DUMMYFUNCTION("""COMPUTED_VALUE"""),"No") -> No | F27: =IFERROR(__xludf.DUMMYFUNCTION("""COMPUTED_VALUE"""),"Yes") -> Yes | G27: =IFERROR(__xludf.DUMMYFUNCTION("""COMPUTED_VALUE"""),1.0) -> 1 | H27: =IFERROR(__xludf.DUMMYFUNCTION("""COMPUTED_VALUE"""),1.0) -> 1 | I27: =IFERROR(__xludf.DUMMYFUNCTION("""COMPUTED_VALUE"""),1.0) -> 1 | J27: =IFERROR(__xludf.DUMMYFUNCTION("""COMPUTED_VALUE"""),0.5) -> 0.5 | K27: =IFERROR(__xludf.DUMMYFUNCTION("""COMPUTED_VALUE"""),"4– Usable, minor flaws Minor background noise.") -> 4– Usable, minor flaws Minor background noise. | L27: =IFERROR(__xludf.DUMMYFUNCTION("""COMPUTED_VALUE"""),"No") -> No
A28: =IFERROR(__xludf.DUMMYFUNCTION("""COMPUTED_VALUE"""),"collect\read\YouTube\Bangladesh Television (BTV)\__yFg8a8Zb4\83084b41-cdbf-4374-9d5b-96e11f83f21b.flac") -> collect\read\YouTube\Bangladesh Television (BTV)\__yFg8a8Zb4\83084b41-cdbf-4374-9d5b-96e11f83f21b.flac | B28: =IFERROR(__xludf.DUMMYFUNCTION("""COMPUTED_VALUE"""),30.0) -> 30 | C28: =IFERROR(__xludf.DUMMYFUNCTION("""COMPUTED_VALUE"""),"আনন্দের বিষয় তো আমি বাস্তবতাটা বুছিলাম এই গত সপ্তাহে কিন্তু গত সপ্তাহে না গত দুই দিন আগে কিন্তু জি সেভেন্ট সম্মেলন শেষ হলো শুভাষ আপনি নিশ্চয় খেয়াল করেছেন এই জি সেভেনে তারা যে সাতটা দেশে তাদের যে সম্মিলিত সিদ্ধান্ত তারা কিন্তু এখন বলেছে যে এক বিলিয়ন ডোজ টি"&"কা তারা কিন্তু আপনার এই দরিদ্র দেশগুলোকে গি বেবাই করবে মানে হলো ফ্রী তারাইডলা ডিস্ট্রিবিউট করবেন অনেট করবেন ইনস্টিডফ ওপেনিং আপ দ্য পেটেন্ট রাইট তারা কিন্তু এই ফ্রিড অনেশনের দিকে এখন যাচ্ছে") -> আনন্দের বিষয় তো আমি বাস্তবতাটা বুছিলাম এই গত সপ্তাহে কিন্তু গত সপ্তাহে না গত দুই দিন আগে কিন্তু জি সেভেন্ট সম্মেলন শেষ হলো শুভাষ আপনি নিশ্চয় খেয়াল করেছেন এই জি সেভেনে তারা যে সাতটা দেশে তাদের যে সম্মিলিত সিদ্ধান্ত তারা কিন্তু এখন বলেছে যে এক বিলিয়ন ডোজ টিকা তারা কিন্তু আপনার এই দরিদ্র দেশগুলোকে গি বেবাই করবে মানে হলো ফ্রী তারাইডলা ডিস্ট্রিবিউট করবেন অনেট করবেন ইনস্টিডফ ওপেনিং আপ দ্য পেটেন্ট রাইট তারা কিন্তু এই ফ্রিড অনেশনের দিকে এখন যাচ্ছে | D28: =IFERROR(__xludf.DUMMYFUNCTION("""COMPUTED_VALUE"""),"No") -> No | E28: =IFERROR(__xludf.DUMMYFUNCTION("""COMPUTED_VALUE"""),"Yes") -> Yes | F28: =IFERROR(__xludf.DUMMYFUNCTION("""COMPUTED_VALUE"""),"Yes") -> Yes | G28: =IFERROR(__xludf.DUMMYFUNCTION("""COMPUTED_VALUE"""),0.5) -> 0.5 | H28: =IFERROR(__xludf.DUMMYFUNCTION("""COMPUTED_VALUE"""),0.5) -> 0.5 | I28: =IFERROR(__xludf.DUMMYFUNCTION("""COMPUTED_VALUE"""),0.5) -> 0.5 | J28: =IFERROR(__xludf.DUMMYFUNCTION("""COMPUTED_VALUE"""),0.5) -> 0.5 | K28: =IFERROR(__xludf.DUMMYFUNCTION("""COMPUTED_VALUE"""),"4– Usable, minor flaws Minor background noise.") -> 4– Usable, minor flaws Minor background noise. | L28: =IFERROR(__xludf.DUMMYFUNCTION("""COMPUTED_VALUE"""),"No") -> No
